Workbook

Sheet Dashboard
A1: DUTCH BROS ($BROS) — DASHBOARD — 2026-08-10
A2: Quarterly update of 2026-06-05 analysis. Blue = hardcoded inputs, black = formulas, green = cross-sheet links.
A4: MARKET DATA
A5: Current price (Aug 10, 2026 close) | B5: 51.29
A6: 52-week high / low | B6: $74.65 / $44.58
A7: Fully exchanged diluted shares (M) | B7: 180
A8: Market cap ($M) | B8: =B5*B7 -> 9232.2
A9: Net cash ($M) | B9: 74
A10: Enterprise value ($M) | B10: =B8-B9 -> 9158.2
A11: EV / FY2026E EBITDA ($387.5M guide mid) | B11: =B10/387.5 -> 23.634065
A13: Q2 2026 ACTUALS (8-K, Aug 5 2026)
A14: Revenue ($M) | B14: 550.9
A15: Revenue growth YoY | B15: 0.325
A16: Systemwide SSS | B16: 0.058
A17: Systemwide transaction growth | B17: 0.017
A18: Co-op shop contribution margin | B18: 0.306
A19: Adj. EBITDA ($M) | B19: 113.7
A20: Adj. EPS (fully exchanged) | B20: 0.33
A21: Total shops (period end) | B21: 1225
A23: FY2026 GUIDANCE (RAISED AUG 5)
A24: Revenue | B24: $2.10–$2.13B (was $2.05–$2.08B)
A25: Systemwide SSS | B25: 5–6%
A26: Adj. EBITDA | B26: $385–$390M (was $370–$380M)
A27: Capex | B27: $350–$370M
A28: System shop openings | B28: ≥185
A30: DCF INTRINSIC VALUE (EBITDA-TERMINAL, 12% WACC)
A31: Scenario | B31: Bear | C31: Base | D31: Bull
A32: Intrinsic price / share | B32: =BROS_Model!B38 -> 25.913847 | C32: =BROS_Model!B64 -> 58.768799 | D32: =BROS_Model!B90 -> 96.515473
A33: vs current price | B33: =B32/$B$5-1 -> -0.49475829 | C33: =C32/$B$5-1 -> 0.14581398 | D33: =D32/$B$5-1 -> 0.88176004
A36: TECHNICAL SNAPSHOT
A37: 20-day SMA | B37: 63.28
A38: 50-day SMA | B38: 64.21
A39: 200-day SMA | B39: 57.24
A40: RSI (14) | B40: 20
A41: Support | B41: $50–51, then $44.58
A42: Resistance | B42: $57–58 (200d), $63–64 (20/50d)

Sheet BROS_Model
A1: DUTCH BROS ($BROS) — DCF MODEL (EBITDA-TERMINAL METHOD) — 2026-08-10
A2: Single 12% WACC across all scenarios. Terminal EV/EBITDA calibrated to terminal EBITDA margin. Restaurant methodology (not FCF Gordon Growth).
A4: GLOBAL INPUTS (blue = hardcoded)
A5: FY2026 Revenue — guidance midpoint ($M) | B5: 2115
A6: FY2026 Adj. EBITDA — guidance midpoint ($M) | B6: 387.5
A7: WACC (single rate, all scenarios) | B7: 0.12
A8: Net cash ($M) | B8: 74
A9: Fully exchanged diluted shares (M) | B9: 180
A10: Years to terminal (FY2030 year-end) | B10: 4.4
A11: Cash taxes (% of EBITDA, simplification) | B11: 0.15
A12: Capex % of revenue — FY2026 | B12: 0.17
A13: Capex % of revenue — FY2030 (glide) | B13: 0.1
A15: BEAR CASE — SSS decelerates to 2–3%, traffic goes negative, margins compress; openings slow
A16: Revenue CAGR FY26→FY30 | B16: 0.12
A17: Terminal EBITDA margin (FY2030) | B17: 0.18
A18: Terminal EV/EBITDA multiple | B18: 12
A20: Projection ($M) | C20: 2026 | D20: 2027 | E20: 2028 | F20: 2029 | G20: 2030
A21: Revenue | C21: =$B$5 -> 2115 | D21: =C21*(1+$B$16) -> 2368.8 | E21: =D21*(1+$B$16) -> 2653.056 | F21: =E21*(1+$B$16) -> 2971.4227 | G21: =F21*(1+$B$16) -> 3327.9934
A22: EBITDA margin % | C22: =$B$6/$B$5 -> 0.18321513 | D22: =$B$6/$B$5+($B$17-$B$6/$B$5)*1/4 -> 0.18241135 | E22: =$B$6/$B$5+($B$17-$B$6/$B$5)*2/4 -> 0.18160757 | F22: =$B$6/$B$5+($B$17-$B$6/$B$5)*3/4 -> 0.18080378 | G22: =$B$6/$B$5+($B$17-$B$6/$B$5)*4/4 -> 0.18
A23: EBITDA | C23: =C21*C22 -> 387.5 | D23: =D21*D22 -> 432.096 | E23: =E21*E22 -> 481.81504 | F23: =F21*F22 -> 537.24447 | G23: =G21*G22 -> 599.03882
A24: Capex % rev | C24: =$B$12+($B$13-$B$12)*0/4 -> 0.17 | D24: =$B$12+($B$13-$B$12)*1/4 -> 0.1525 | E24: =$B$12+($B$13-$B$12)*2/4 -> 0.135 | F24: =$B$12+($B$13-$B$12)*3/4 -> 0.1175 | G24: =$B$12+($B$13-$B$12)*4/4 -> 0.1
A25: Capex | C25: =C21*C24 -> 359.55 | D25: =D21*D24 -> 361.242 | E25: =E21*E24 -> 358.16256 | F25: =F21*F24 -> 349.14217 | G25: =G21*G24 -> 332.79934
A26: Cash taxes | C26: =C23*$B$11 -> 58.125 | D26: =D23*$B$11 -> 64.8144 | E26: =E23*$B$11 -> 72.272256 | F26: =F23*$B$11 -> 80.58667 | G26: =G23*$B$11 -> 89.855823
A27: FCF | C27: =C23-C25-C26 -> -30.175 | D27: =D23-D25-D26 -> 6.0396 | E27: =E23-E25-E26 -> 51.380224 | F27: =F23-F25-F26 -> 107.51563 | G27: =G23-G25-G26 -> 176.38365
A28: Discount factor | C28: 0 | D28: =1/(1+$B$7)^(1+0.4) -> 0.85328629 | E28: =1/(1+$B$7)^(2+0.4) -> 0.76186276 | F28: =1/(1+$B$7)^(3+0.4) -> 0.68023461 | G28: =1/(1+$B$7)^(4+0.4) -> 0.60735233
A29: PV of FCF | C29: =C27*C28 -> 0 | D29: =D27*D28 -> 5.1535079 | E29: =E27*E28 -> 39.144679 | F29: =F27*F28 -> 73.135851 | G29: =G27*G28 -> 107.12702
A31: Terminal EV (FY30 EBITDA × multiple) ($M) | B31: =G23*$B$18 -> 7188.4658
A32: PV of Terminal Value ($M) | B32: =G23*$B$18/(1+$B$7)^$B$10 -> 4365.9315
A33: PV of interim FCF FY27–FY30 ($M) | B33: =SUM(D29:G29) -> 224.56106
A34: Enterprise Value ($M) | B34: =B32+B33 -> 4590.4925
A35: + Net cash ($M) | B35: =$B$8 -> 74
A36: Equity Value ($M) | B36: =B34+B35 -> 4664.4925
A37: ÷ Fully exchanged diluted shares (M) | B37: =$B$9 -> 180
A38: INTRINSIC PRICE / SHARE | B38: =B36/B37 -> 25.913847
A41: BASE CASE — 18–20% revenue growth; SSS normalizes 4–5%; margins expand to 22% by FY2030
A42: Revenue CAGR FY26→FY30 | B42: 0.185
A43: Terminal EBITDA margin (FY2030) | B43: 0.22
A44: Terminal EV/EBITDA multiple | B44: 18
A46: Projection ($M) | C46: 2026 | D46: 2027 | E46: 2028 | F46: 2029 | G46: 2030
A47: Revenue | C47: =$B$5 -> 2115 | D47: =C47*(1+$B$42) -> 2506.275 | E47: =D47*(1+$B$42) -> 2969.9359 | F47: =E47*(1+$B$42) -> 3519.374 | G47: =F47*(1+$B$42) -> 4170.4582
...

Sheet Unit_Economics
A1: UNIT ECONOMICS + PEER COMPS + LEADERSHIP SCORECARD
A2: Restaurant methodology — Rule of 40 replaced by unit-economics scorecard (see non-SaaS adaptations).
A4: UNIT ECONOMICS SCORECARD (Q2 2026)
A5: Metric | B5: Value | C5: Watch
A6: Systemwide SSS | B6: +5.8% | C6: Q3 guide 4–5% = deceleration
A7: System transaction growth | B7: +1.7% | C7: ALERT if negative — was +3.7% PY
A8: Avg ticket growth | B8: +4.1% | C8: Pricing contribution <1% in H2'26
A9: Co-op contribution margin | B9: 30.6% | C9: vs 31.1% PY; coffee + occupancy pressure
A10: Adj. EBITDA margin | B10: 20.6% | C10: vs 21.4% PY
A11: Net new shops (Q2 / H1) | B11: 48 / 89 | C11: On track for ≥185 FY26
A12: Total shops | B12: 1,225 of 4,000+ potential | C12: ~31% penetration; 2,029-shop 2029 goal, ~90% pipeline secured
A13: Est. AUV (systemwide) | B13: ~$2.2M (est.) | C13: Q1'26 was $2.16M +6.6% YoY
A16: PEER COMPARABLES (approximate, Aug 2026)
A17: Company | B17: Ticker | C17: SSS % | D17: RL margin % | E17: EV/EBITDA (fwd) | F17: Rev growth (fwd) | G17: Note
A18: Dutch Bros | B18: BROS | C18: +5.8% | D18: ~31% | E18: ~24x | F18: ~25–28% | G18: Subject — fastest grower in set
A19: Starbucks | B19: SBUX | C19: ~+1–3% | D19: n/a | E19: ~16–18x | F19: ~3–5% | G19: Scale leader, traffic-challenged
A20: Chipotle | B20: CMG | C20: ~+2–4% | D20: ~26–27% | E20: ~24–27x | F20: ~10–12% | G20: Margin benchmark
A21: CAVA | B21: CAVA | C21: ~+5–8% | D21: ~25% | E21: ~40x+ | F21: ~20–25% | G21: Closest growth comp, richer multiple
A22: Shake Shack | B22: SHAK | C22: ~+2–4% | D22: ~21–22% | E22: ~22–26x | F22: ~12–15% | G22: Mid-growth fast casual
A23: Wingstop | B23: WING | C23: ~flat–+3% | D23: n/a (franchise) | E23: ~38–45x | F23: ~15–20% | G23: Franchise model premium
A24: 7 Brew | B24: Private | C24: n/a | D24: n/a | E24: n/a | F24: Rapid | G24: Most direct drive-thru competitor
A25: Peer figures are approximate (Aug 2026 web sources); directional context only.
A27: LEADERSHIP SCORECARD (Nash-style, 0/5/10 — evidence required)
A28: CEO: Christine Barone (hired, since Jan 2024; ex-Starbucks SVP, ex-True Food Kitchen CEO)
A29: Founder: Travis Boersma, Executive Chairman — 38.8% economic / 73.1% voting (Class B 10:1 super-vote)
A31: Criterion | B31: Score (0/5/10) | C31: Evidence
A32: Execution track record | B32: 10 | C32: Q2'26 beat; FY26 rev guide raised to $2.10–2.13B and EBITDA to $385–390M; 32.5% rev growth; 89 H1 openings on ≥185 pace
A33: Founder / tenure / skin in game | B33: 5 | C33: Founder Exec Chairman w/ 38.8% economic stake; but hired CEO tenure only 2.5 yrs; founder in programmatic sell-down
A34: Capital allocation | B34: 5 | C34: Opportunistic distressed site buys (Clutch $20M/20 sites; Salad and Go $105M/65 sites) vs heavy capex $350–370M, negative FCF, no buybacks
A35: Insider activity (Form 4) | B35: 5 | C35: No open-market buys; chair-linked entities sold 2.25M sh H1'26 @$60–64 — all 10b5-1 (routine); CEO sold 42k 10b5-1
A36: Governance & alignment | B36: 5 | C36: Dual-class: Boersma 73.1% votes vs 38.8% economics (Class B 10 votes/sh, sunset <5%); separate CEO/Chair; no restatements
A37: COMPOSITE (max 50) | B37: =SUM(B32:B36) -> 30 | C37: =IF(B37>=40,"Strong — feeds Bull Case",IF(B37>=25,"Neutral — not a differentiator","Risk — feeds Bear Case")) -> Neutral — not a differentiator

Sheet Options_Strategy
A1: OPTIONS STRATEGY — LONG EQUITY HOLDER OVERLAY
A3: MARKET DATA REFERENCE
A4: Current price | B4: 51.29
A5: Est. IV (post-earnings) | B5: ~45–55% (est.)
A6: DCF base (model) | B6: =BROS_Model!B64 -> 58.768799
A7: DCF bear (model) | B7: =BROS_Model!B38 -> 25.913847
A8: Support / Resistance | B8: $50–51 / $57–58
A10: RECOMMENDED STRATEGIES (premiums are estimates — verify live)
A11: Strategy | B11: Structure | C11: Expiry | D11: Est. premium | E11: Max gain | F11: Max loss | G11: Rationale
A12: Covered Call (income) | B12: Sell $57.5–$60 Call | C12: 6–8 wks | D12: ~$1.30–$1.90/sh (~2.5–3.5% per cycle) | E12: Premium + upside to strike | F12: Shares called away above strike (opportunity cost) | G12: Strike sits at 200-day SMA / gap-fill resistance; per-cycle yield (NOT annualized)
A13: Cash-Secured Put (accumulate) | B13: Sell $47.5 Put | C13: 6–8 wks | D13: ~$1.60–$2.20/sh (~3.4–4.6% per cycle) | E13: Keep premium if >$47.5 at expiry | F13: $4,530/contract if BROS → $0 (assigned at $47.5 − premium) | G13: Effective entry ~$45.5–46 — ~22% below rebuilt DCF base; disciplined add level
A14: CSP ladder (aggressive add) | B14: Sell $45 Put | C14: 8–10 wks | D14: ~$1.20–$1.70/sh (~2.7–3.8% per cycle) | E14: Keep premium if >$45 | F14: $4,330/contract at max ($45 − premium) | G14: Assignment near 52-wk low $44.58; only if sized for bear case $26
A16: Sizing rule: compute max loss in dollars before sizing. Bear-case DCF is ~$26 — size so a move there is acceptable. Yields are per-cycle, not annualized.
