Workbook

Sheet Dashboard
A1: INVESTMENT ANALYSIS DASHBOARD — PLTR vs NOW | June 2026
A3: PALANTIR TECHNOLOGIES (PLTR) | E3: SERVICENOW (NOW)
A4: Metric | B4: Value | C4: Notes/Source | E4: Metric | F4: Value | G4: Notes/Source
A5: Company | B5: Palantir Technologies | E5: Company | F5: ServiceNow, Inc.
A6: Ticker | B6: PLTR | E6: Ticker | F6: NOW
A7: Current Price ($) | B7: =PLTR_Model!$B$51 -> 141.51 | E7: Current Price ($) | F7: =NOW_Model!$B$53 -> 119.29
A8: Market Cap ($B, approx.) | B8: =PLTR_Model!$B$51*PLTR_Model!$B$50/1000 -> 363.82221 | C8: Price x Diluted Shares | E8: Market Cap ($B, approx.) | F8: =NOW_Model!$B$53*NOW_Model!$B$52/1000 -> 124.0616 | G8: Price x Diluted Shares
A9: FY2026 Revenue ($M, Base) | B9: =PLTR_Model!B36 -> 7655.67 | C9: Base scenario | E9: FY2026 Revenue ($M, Base) | F9: =NOW_Model!B39 -> 16100 | G9: Base scenario
A10: FY2026 Rev Growth (Base) | B10: =PLTR_Model!B35 -> 0.71 | C10: Base scenario | E10: FY2026 Rev Growth (Base) | F10: =NOW_Model!B38 -> 0.22 | G10: Base scenario
A11: Gross Margin (Q1 2026) | B11: 0.87 | C11: Q1 2026 actual | E11: Gross Margin (Q1 2026) | F11: 0.795 | G11: Non-GAAP Q1 2026
A12: Adj. Op Margin (Q1 2026) | B12: 0.6 | C12: Adj./Non-GAAP | E12: Non-GAAP Op Margin (Q1 '26) | F12: 0.32 | G12: Non-GAAP Q1 2026
A13: FCF Margin (Q1 2026) | B13: 0.57 | C13: Adj. FCF margin | E13: FCF Margin (Q1 2026) | F13: 0.44 | G13: Non-GAAP
A14: Rule of 40 (Q1 2026) | B14: 145 | C14: 85%+60%=145 | E14: Rule of 40 (Q1 2026) | F14: 54 | G14: 22%+32%=54
A15: EV/Sales FY2026 (est.) | B15: 46.5 | C15: Analyst est. | E15: EV/Sales FY2026 (est.) | F15: 7.5 | G15: Analyst est.
A16: EV/FCF FY2026 (est.) | B16: 82.7 | C16: Analyst est. | E16: EV/FCF FY2026 (est.) | F16: 21.3 | G16: Analyst est.
A17: DCF Intrinsic — Bull ($) | B17: =PLTR_Model!$B$64 -> 71.383872 | C17: Linked from model | E17: DCF Intrinsic — Bull ($) | F17: =NOW_Model!$B$66 -> 178.71138 | G17: Linked from model
A18: DCF Intrinsic — Base ($) | B18: =PLTR_Model!$B$78 -> 40.157794 | C18: Linked from model | E18: DCF Intrinsic — Base ($) | F18: =NOW_Model!$B$80 -> 126.26237 | G18: Linked from model
A19: DCF Intrinsic — Bear ($) | B19: =PLTR_Model!$B$92 -> 20.504545 | C19: Linked from model | E19: DCF Intrinsic — Bear ($) | F19: =NOW_Model!$B$94 -> 81.037468 | G19: Linked from model
A20: Price vs DCF Base (%) | B20: =(PLTR_Model!$B$51-PLTR_Model!$B$78)/PLTR_Model!$B$78 -> 2.523849 | C20: (-) = premium | E20: Price vs DCF Base (%) | F20: =(NOW_Model!$B$53-NOW_Model!$B$80)/NOW_Model!$B$80 -> -0.055221248 | G20: (-) = premium
A21: IV (%) | B21: 0.6879 | C21: June 2026 | E21: IV (%, estimate) | G21: Verify live
A22: IV Rank | B22: 46.73 | C22: June 2026 | E22: IV Rank (estimate) | G22: Verify live
A23: 200-day SMA ($) | B23: 162 | C23: June 2026 | E23: 52-wk High ($) | F23: 211.48 | G23: 52-wk range
A24: 52-Week High (est., $) | C24: ~$170 est. | E24: 52-wk Low ($) | F24: 81.24 | G24: 52-wk range
A25: 52-Week Low (est., $) | C25: ~$70 est. | E25: 200-day SMA ($) | G25: Verify live
A28: COLOR CODING LEGEND
A29: Blue text | B29: Hardcoded inputs — user-editable assumptions and market data
A30: Black text | B30: Formulas and calculated outputs
A31: Green text | B31: Cross-sheet links pulling data from PLTR_Model or NOW_Model
A32: Gold background | B32: Key output cells: DCF intrinsic values, Rule of 40 scores

Sheet PLTR_Model
A1: PALANTIR TECHNOLOGIES (PLTR) — Investment Analysis Model
A2: SECTION A — HISTORICAL DATA (FY2024–Q1 2026)
A3: Metric | B3: FY2024 | C3: FY2025 | D3: Q1 2025 | E3: Q2 2025 | F3: Q3 2025 | G3: Q4 2025 | H3: Q1 2026
A4: Revenue ($M) | B4: 2865 | C4: 4477 | D4: 883.9 | E4: 1004 | F4: 1181 | G4: 1408 | H4: 1632.6
A5: YoY Revenue Growth | C5: 0.563 | H5: 0.869
A6: Gross Margin | H6: 0.87
A7: Adj. Operating Margin | B7: 0.36 | C7: 0.5 | H7: 0.6
A8: GAAP Operating Margin | H8: 0.46
A9: Adj. FCF Margin | H9: 0.57
A10: Adj. FCF ($M) | C10: 2239
A11: Adj. EBITDA ($M) | H11: 990.3
A12: Adj. EBITDA Margin | H12: 0.61
A13: SBC ($M) | H13: 201.6
A14: SBC % of Revenue | H14: 0.123
A16: Revenue Segment Detail (Q1 2026)
A17: Metric | B17: Q1 2026 ($M) | C17: YoY Growth
A18: US Revenue ($M) | B18: 1282 | C18: 1.04
A19: US Commercial Revenue ($M) | B19: 595 | C19: 1.33
A20: US Government Revenue ($M) | B20: 687 | C20: 0.84
A21: International Revenue ($M) | B21: 351
A22: Total Customers (TTM) | B22: 1007
A25: SECTION B — REVENUE & FCF PROJECTIONS (FY2026–FY2030)
A26: FY2025 Revenue ($M) [Base year for projections] | B26: 4477
A27: Year | B27: FY2026 | C27: FY2027 | D27: FY2028 | E27: FY2029 | F27: FY2030
A28: Bull Scenario
A29: Bull Rev Growth Assumption | B29: 0.71 | C29: 0.6 | D29: 0.5 | E29: 0.4 | F29: 0.3
A30: Bull Revenue ($M) | B30: =$B$26*(1+B29) -> 7655.67 | C30: =B30*(1+C29) -> 12249.072 | D30: =C30*(1+D29) -> 18373.608 | E30: =D30*(1+E29) -> 25723.051 | F30: =E30*(1+F29) -> 33439.967
A31: Bull FCF Margin Assumption | B31: 0.58 | C31: 0.6 | D31: 0.62 | E31: 0.62 | F31: 0.62
A32: Bull FCF ($M) | B32: =B30*B31 -> 4440.2886 | C32: =C30*C31 -> 7349.4432 | D32: =D30*D31 -> 11391.637 | E32: =E30*E31 -> 15948.292 | F32: =F30*F31 -> 20732.779
A34: Base Scenario
A35: Base Rev Growth Assumption | B35: 0.71 | C35: 0.5 | D35: 0.35 | E35: 0.25 | F35: 0.18
A36: Base Revenue ($M) | B36: =$B$26*(1+B35) -> 7655.67 | C36: =B36*(1+C35) -> 11483.505 | D36: =C36*(1+D35) -> 15502.732 | E36: =D36*(1+E35) -> 19378.415 | F36: =E36*(1+F35) -> 22866.529
A37: Base FCF Margin Assumption | B37: 0.56 | C37: 0.56 | D37: 0.55 | E37: 0.54 | F37: 0.52
A38: Base FCF ($M) | B38: =B36*B37 -> 4287.1752 | C38: =C36*C37 -> 6430.7628 | D38: =D36*D37 -> 8526.5025 | E38: =E36*E37 -> 10464.344 | F38: =F36*F37 -> 11890.595
A40: Bear Scenario
A41: Bear Rev Growth Assumption | B41: 0.71 | C41: 0.35 | D41: 0.2 | E41: 0.15 | F41: 0.1
A42: Bear Revenue ($M) | B42: =$B$26*(1+B41) -> 7655.67 | C42: =B42*(1+C41) -> 10335.155 | D42: =C42*(1+D41) -> 12402.185 | E42: =D42*(1+E41) -> 14262.513 | F42: =E42*(1+F41) -> 15688.765
A43: Bear FCF Margin Assumption | B43: 0.52 | C43: 0.5 | D43: 0.47 | E43: 0.44 | F43: 0.4
A44: Bear FCF ($M) | B44: =B42*B43 -> 3980.9484 | C44: =C42*C43 -> 5167.5773 | D44: =D42*D43 -> 5829.0271 | E44: =E42*E43 -> 6275.5058 | F44: =F42*F43 -> 6275.5058
A47: SECTION C — DCF VALUATION
...

Sheet NOW_Model
A1: SERVICENOW (NOW) — Investment Analysis Model
A2: SECTION A — HISTORICAL DATA (FY2025–Q1 2026)
A3: Metric | B3: FY2025 | C3: Q1 2026
A4: Subscription Revenue ($M) | B4: 12840 | C4: 3671
A5: Total Revenue ($M) | B5: 13285 | C5: 3770
A6: Sub Revenue YoY Growth | B6: 0.21 | C6: 0.22
A7: GAAP Gross Margin | C7: 0.75
A8: Non-GAAP Gross Margin | C8: 0.795
A9: Sub Gross Margin (GAAP) | C9: 0.775
A10: Sub Gross Margin (Non-GAAP) | C10: 0.815
A11: Non-GAAP Operating Margin | C11: 0.32
A12: Non-GAAP FCF Margin | B12: 0.4 | C12: 0.44
A13: cRPO ($M) | C13: 12640
A14: cRPO YoY Growth | C14: 0.225
A15: Total RPO ($M) | C15: 27700
A16: Total RPO YoY Growth | C16: 0.25
A17: SBC ($M) | C17: 547
A18: SBC % of Revenue | C18: 0.145
A20: SECTION D — KEY SaaS METRICS (Q1 2026)
A21: Metric | B21: Value | C21: Growth / Note
A22: Customers >$5M ACV | B22: 630 | C22: +22% YoY
A23: Transactions >$5M ACV (Q1) | B23: 16 | C23: +80% YoY
A24: Now Assist >$1M ACV Customers | C24: +130% YoY
A27: SECTION B — REVENUE & FCF PROJECTIONS (FY2026–FY2030)
A28: FY2025 Total Revenue ($M) [Base year] | B28: 13285
A29: FY2026 Guided Revenue ($M) [Sub $15,755M + PS ~$345M] | B29: 16100
A30: Year | B30: FY2026 | C30: FY2027 | D30: FY2028 | E30: FY2029 | F30: FY2030
A31: Bull Scenario
A32: Bull Rev Growth Assumption | B32: 0.22 | C32: 0.22 | D32: 0.2 | E32: 0.18 | F32: 0.16
A33: Bull Revenue ($M) | B33: =$B$29 -> 16100 | C33: =B33*(1+C32) -> 19642 | D33: =C33*(1+D32) -> 23570.4 | E33: =D33*(1+E32) -> 27813.072 | F33: =E33*(1+F32) -> 32263.164
A34: Bull FCF Margin Assumption | B34: 0.37 | C34: 0.4 | D34: 0.42 | E34: 0.43 | F34: 0.44
A35: Bull FCF ($M) | B35: =B33*B34 -> 5957 | C35: =C33*C34 -> 7856.8 | D35: =D33*D34 -> 9899.568 | E35: =E33*E34 -> 11959.621 | F35: =F33*F34 -> 14195.792
A37: Base Scenario
A38: Base Rev Growth Assumption | B38: 0.22 | C38: 0.2 | D38: 0.18 | E38: 0.15 | F38: 0.12
A39: Base Revenue ($M) | B39: =$B$29 -> 16100 | C39: =B39*(1+C38) -> 19320 | D39: =C39*(1+D38) -> 22797.6 | E39: =D39*(1+E38) -> 26217.24 | F39: =E39*(1+F38) -> 29363.309
A40: Base FCF Margin Assumption | B40: 0.35 | C40: 0.37 | D40: 0.39 | E40: 0.4 | F40: 0.41
A41: Base FCF ($M) | B41: =B39*B40 -> 5635 | C41: =C39*C40 -> 7148.4 | D41: =D39*D40 -> 8891.064 | E41: =E39*E40 -> 10486.896 | F41: =F39*F40 -> 12038.957
A43: Bear Scenario
A44: Bear Rev Growth Assumption | B44: 0.22 | C44: 0.15 | D44: 0.12 | E44: 0.1 | F44: 0.08
A45: Bear Revenue ($M) | B45: =$B$29 -> 16100 | C45: =B45*(1+C44) -> 18515 | D45: =C45*(1+D44) -> 20736.8 | E45: =D45*(1+E44) -> 22810.48 | F45: =E45*(1+F44) -> 24635.318
...

Sheet Comparison
A1: PLTR vs NOW — Comparative Analysis
A3: RULE OF 40 COMPARISON (Q1 2026)
A4: Company | B4: Revenue Growth | C4: FCF/Op Margin | D4: Rule of 40 | E4: Forward EV/S | F4: EV/FCF | G4: Notes
A5: PLTR (Q1 2026) | B5: 0.85 | C5: 0.6 | D5: =(B5+C5)*100 -> 145 | E5: 46.5 | F5: 82.7 | G5: Adj. op margin; AI infrastructure
A6: NOW (Q1 2026) | B6: 0.22 | C6: 0.32 | D6: =(B6+C6)*100 -> 54 | E6: 7.5 | F6: 21.3 | G6: Non-GAAP op margin; Enterprise workflow
A9: PEER COMPARABLES TABLE (Approximate, June 2026 — VERIFY BEFORE USE)
A10: Company | B10: Ticker | C10: Fwd Rev Growth | D10: FCF Margin | E10: Rule of 40 | F10: Fwd EV/S | G10: Segment / Comment
A11: Palantir | B11: PLTR | C11: 0.71 | D11: 0.56 | E11: =(C11+D11)*100 -> 127 | F11: 46.5 | G11: AI infrastructure / data analytics
A12: ServiceNow | B12: NOW | C12: 0.22 | D12: 0.35 | E12: =(C12+D12)*100 -> 57 | F12: 7.5 | G12: Enterprise workflow / AI platform
A13: Salesforce | B13: CRM | C13: 0.09 | D13: 0.32 | E13: =(C13+D13)*100 -> 41 | F13: 6.5 | G13: CRM / cloud applications
A14: Snowflake | B14: SNOW | C14: 0.23 | D14: 0.18 | E14: =(C14+D14)*100 -> 41 | F14: 10 | G14: Data cloud / analytics platform
A15: Datadog | B15: DDOG | C15: 0.23 | D15: 0.25 | E15: =(C15+D15)*100 -> 48 | F15: 14 | G15: Observability / monitoring
A16: CrowdStrike | B16: CRWD | C16: 0.2 | D16: 0.28 | E16: =(C16+D16)*100 -> 48 | F16: 20 | G16: Cybersecurity / endpoint protection
A17: Workday | B17: WDAY | C17: 0.14 | D17: 0.25 | E17: =(C17+D17)*100 -> 39 | F17: 6 | G17: HCM / Finance cloud
A19: NOTE: Peer comps are approximate estimates as of June 2026. Verify against current Bloomberg/FactSet before use.
A21: VALUATION SUMMARY — CURRENT PRICE vs DCF INTRINSIC VALUE
A22: Company | B22: Current Price | C22: DCF Bull | D22: DCF Base | E22: DCF Bear | F22: vs Bull (%) | G22: vs Base (%)
A23: PLTR | B23: =PLTR_Model!$B$51 -> 141.51 | C23: =PLTR_Model!$B$64 -> 71.383872 | D23: =PLTR_Model!$B$78 -> 40.157794 | E23: =PLTR_Model!$B$92 -> 20.504545 | F23: =(B23-C23)/C23 -> 0.98238055 | G23: =(B23-D23)/D23 -> 2.523849
A24: NOW | B24: =NOW_Model!$B$53 -> 119.29 | C24: =NOW_Model!$B$66 -> 178.71138 | D24: =NOW_Model!$B$80 -> 126.26237 | E24: =NOW_Model!$B$94 -> 81.037468 | F24: =(B24-C24)/C24 -> -0.33249913 | G24: =(B24-D24)/D24 -> -0.055221248

Sheet Options_Strategy
A1: OPTIONS STRATEGY — PLTR & NOW (June 2026)
A3: MARKET DATA REFERENCE (June 2026)
A4: Ticker | B4: Price | C4: IV (%) | D4: IV Rank | E4: 200-day SMA | F4: 52-wk Low | G4: 52-wk High | H4: RSI (est.) | I4: Notes
A5: PLTR | B5: 141.51 | C5: 0.6879 | D5: 46.73 | E5: 162 | I5: IV 68.79%; IVR 46.73; trades ~12% below 200-day SMA of $162
A6: NOW | B6: 119.29 | F6: 81.24 | G6: 211.48 | I6: 52-wk range $81.24-$211.48; near lower historical range
A9: OPTIONS STRATEGIES SUMMARY TABLE
A10: Strategy | B10: Ticker | C10: Structure | D10: Strike(s) | E10: Expiry | F10: Premium (est.) | G10: Max Gain | H10: Max Loss | I10: Rationale
A11: 1 — Bear Call Spread | B11: PLTR | C11: Sell $155 Call / Buy $165 Call | D11: $155 / $165 | E11: Aug 2026 (~2mo) | F11: ~$3-4 credit | G11: ~$3-4 credit | H11: ~$6-7 per spread | I11: PLTR trades far above DCF intrinsic; moderate IVR 46.73 supports premium selling; protects existing holders from stall scenarios
A12: 2 — Covered Call | B12: PLTR | C12: Sell OTM Call vs long shares | D12: $155-160 | E12: 6-8 weeks out | F12: ~$5-7/contract | G12: ~$5-7 premium | H12: Uncapped above strike | I12: At ~69% IV, significant premium income; reduces cost basis; best for long holders not expecting near-term rally
A13: 3 — Cash-Secured Put | B13: PLTR | C13: Sell OTM Put / Hold cash | D13: $120-125 | E13: ~8 weeks out | F13: ~$8-10 | G13: ~$8-10 premium | H13: Assigned at ~$110-117 | I13: Effective cost basis ~$110-117 if assigned (near DCF bull ~$78 zone); income if PLTR holds above strike
A14: 1 — Long Call Spread | B14: NOW | C14: Buy $120 Call / Sell $150 Call | D14: $120 / $150 | E14: Jan 2027 (~7mo) | F14: ~$10-12 debit | G14: ~$18-20 at $150 | H14: ~$10-12 debit | I14: Defined risk bullish play; NOW at/below DCF base case; captures recovery toward $129+ intrinsic value; ~1.7:1 R/R
A15: 2 — Cash-Secured Put | B15: NOW | C15: Sell OTM Put / Hold cash | D15: $110 | E15: 8-10 weeks out | F15: ~$7-9 | G15: ~$7-9 premium | H15: Assigned at ~$101-103 | I15: Entry well below DCF base $129; significant margin of safety if assigned; income generation otherwise
A16: 3 — Covered Call Enh. | B16: NOW | C16: Sell OTM Call vs long shares | D16: $135-140 | E16: 6-8 weeks out | F16: ~$4-6/contract | G16: ~$4-6 premium | H16: Uncapped above strike | I16: Income enhancement for existing NOW holders; generates yield while holding quality name near lows
A19: DISCLAIMER: Options strategies are for educational/analytical purposes only. Verify all premiums with live market data. Options trading involves significant risk of loss. Consult a licensed financial advisor before trading.
