Workbook

Sheet Dashboard
B2: FASTLY, INC. (NASDAQ: FSLY) — INVESTMENT DASHBOARD
B3: Analysis date: August 11, 2026 | Analyst: Ed | Rating: HOLD — Trim into strength; do not add | Vehicle: Long equity (holds shares)
B5: MARKET SNAPSHOT | E5: VALUATION SUMMARY
B6: Current Price | C6: 27.75 | E6: DCF Bull Case / share | F6: =Model!B52 -> 23.587221
B7: 52-Week Range | C7: $6.70 – $34.82 | E7: DCF Base Case / share | F7: =Model!C52 -> 13.368514
B8: Shares Outstanding (M) | C8: 159.3 | E8: DCF Bear Case / share | F8: =Model!D52 -> 6.9275071
B9: Diluted Shares — valuation (M) | C9: 180.3 | E9: Current Price | F9: =C6 -> 27.75
B10: Market Cap ($M) | C10: =C6*C8 -> 4420.575 | E10: Current vs Bull Case | F10: =F9/F6-1 -> 0.17648449
B11: Cash + Marketable Securities ($M) | C11: 337.5 | E11: Base Case vs Current | F11: =F7/F9-1 -> -0.51825173
B12: Total Debt — convertible notes ($M) | C12: 323.96 | E12: FY2026 Guided Revenue ($M, mid) | F12: 739
B13: Net Cash ($M) | C13: =C11-C12 -> 13.54 | E13: FY2026 Rev Growth (guidance) | F13: =F12/Model!B6-1 -> 0.18426071
B14: Enterprise Value ($M) | C14: =C10-C13 -> 4407.035 | E14: FY2026 Non-GAAP Op Inc ($M, mid) | F14: 92
E15: EV / FY26 Revenue | F15: =C14/F12 -> 5.9635115
B16: FUNDAMENTALS (Most Recent Quarter — Q2 2026) | E16: Rule of 40 (Q2 2026, EBITDA basis) | F16: =Rule_of_40!D15 -> 43.8
B17: Q2 2026 Revenue ($M) | C17: 183.3 | E17: Rule of 40 (FY2025, EBITDA basis) | F17: =Rule_of_40!D7 -> 27.2
B18: Revenue Growth (YoY) | C18: 0.23
B19: Security Revenue ($M) / Growth | C19: $41.7M +43% | E19: TECHNICAL LEVELS
B20: Network Services ($M) / Growth | C20: $133.9M +17% | E20: 20-Day SMA (est.) | F20: 21.5
B21: Other — Compute & Observability | C21: $7.7M +69% | E21: 50-Day SMA | F21: 19.83
B22: GAAP Gross Margin | C22: 0.633 | E22: 200-Day SMA | F22: 17.22
B23: Non-GAAP Gross Margin | C23: 0.658 | E23: RSI (14) | F23: 70.3
B24: Non-GAAP Operating Margin | C24: 0.147 | E24: Short % of Float | F24: 0.181
B25: Adj. EBITDA Margin | C25: 0.208 | E25: Implied Volatility | F25: Elevated (post-spike)
B26: FCF Margin (Q2 — heavy capex) | C26: 0.02
B27: LTM Net Retention Rate | C27: 1.17
B28: Total RPO ($M) — note seq. decline | C28: 341
B29: Top-10 Customer Concentration | C29: 0.37
B31: Color key: blue = hardcoded input | black = formula | green = cross-sheet link. Sources: Fastly Q2 2026 press release (Aug 5, 2026); stockanalysis.com (Aug 11, 2026). Not investment advice.

Sheet Model
A1: FSLY — DCF VALUATION MODEL (5-Year FCF, Gordon Growth Terminal)
A2: SINGLE WACC across all scenarios (mandatory). Only growth, FCF margin & terminal growth vary. Updated for Q2 2026 results + raised FY26 guidance.
A4: HISTORICAL & BASE ($M)
A5: FY2024 Revenue | B5: 543.676
A6: FY2025 Revenue | B6: 624.018
A7: FY2025 Free Cash Flow | B7: 45.809
A8: H1 2026 Revenue (Q1 $173.0 + Q2 $183.3) | B8: 356.3
A9: H1 2026 FCF (heavy capex cycle) | B9: 7.8
A10: FY2026 Guided Revenue (Yr1 base, mid) | B10: 739
A13: ASSUMPTIONS
A14: Assumption | B14: Bull | C14: Base | D14: Bear
A15: WACC (single, all scenarios) | B15: 0.11 | C15: 0.11 | D15: 0.11
A16: Yr2 Revenue Growth (FY2027) | B16: 0.2 | C16: 0.14 | D16: 0.09
A17: Yr3 Revenue Growth | B17: 0.18 | C17: 0.13 | D17: 0.07
A18: Yr4 Revenue Growth | B18: 0.16 | C18: 0.12 | D18: 0.06
A19: Yr5 Revenue Growth | B19: 0.14 | C19: 0.11 | D19: 0.05
A20: Yr1 FCF Margin (FY2026) | B20: 0.08 | C20: 0.07 | D20: 0.06
A21: Yr2 FCF Margin | B21: 0.13 | C21: 0.1 | D21: 0.07
A22: Yr3 FCF Margin | B22: 0.17 | C22: 0.13 | D22: 0.09
A23: Yr4 FCF Margin | B23: 0.22 | C23: 0.16 | D23: 0.11
A24: Yr5 FCF Margin (terminal) | B24: 0.27 | C24: 0.2 | D24: 0.13
A25: Terminal Growth Rate | B25: 0.045 | C25: 0.035 | D25: 0.03
A27: PROJECTIONS — REVENUE ($M)
A28: Year | B28: Bull | C28: Base | D28: Bear
A29: Yr1 (FY2026, guided) | B29: =$B$10 -> 739 | C29: =$B$10 -> 739 | D29: =$B$10 -> 739
A30: Yr2 (FY2027) | B30: =B29*(1+$B$16) -> 886.8 | C30: =C29*(1+$C$16) -> 842.46 | D30: =D29*(1+$D$16) -> 805.51
A31: Yr3 (FY2028) | B31: =B30*(1+$B$17) -> 1046.424 | C31: =C30*(1+$C$17) -> 951.9798 | D31: =D30*(1+$D$17) -> 861.8957
A32: Yr4 (FY2029) | B32: =B31*(1+$B$18) -> 1213.8518 | C32: =C31*(1+$C$18) -> 1066.2174 | D32: =D31*(1+$D$18) -> 913.60944
A33: Yr5 (FY2030) | B33: =B32*(1+$B$19) -> 1383.7911 | C33: =C32*(1+$C$19) -> 1183.5013 | D33: =D32*(1+$D$19) -> 959.28991
A35: PROJECTIONS — FREE CASH FLOW ($M)
A36: Year | B36: Bull | C36: Base | D36: Bear
A37: Yr1 FCF | B37: =B29*$B$20 -> 59.12 | C37: =C29*$C$20 -> 51.73 | D37: =D29*$D$20 -> 44.34
A38: Yr2 FCF | B38: =B30*$B$21 -> 115.284 | C38: =C30*$C$21 -> 84.246 | D38: =D30*$D$21 -> 56.3857
A39: Yr3 FCF | B39: =B31*$B$22 -> 177.89208 | C39: =C31*$C$22 -> 123.75737 | D39: =D31*$D$22 -> 77.570613
A40: Yr4 FCF | B40: =B32*$B$23 -> 267.0474 | C40: =C32*$C$23 -> 170.59478 | D40: =D32*$D$23 -> 100.49704
A41: Yr5 FCF | B41: =B33*$B$24 -> 373.6236 | C41: =C33*$C$24 -> 236.70026 | D41: =D33*$D$24 -> 124.70769
A43: DCF WATERFALL
A44: Item | B44: Bull | C44: Base | D44: Bear
A45: PV of 5-Yr FCF | B45: =B37/(1+$B$15)^1+B38/(1+$B$15)^2+B39/(1+$B$15)^3+B40/(1+$B$15)^4+B41/(1+$B$15)^5 -> 674.54131 | C45: =C37/(1+$C$15)^1+C38/(1+$C$15)^2+C39/(1+$C$15)^3+C40/(1+$C$15)^4+C41/(1+$C$15)^5 -> 458.31602 | D45: =D37/(1+$D$15)^1+D38/(1+$D$15)^2+D39/(1+$D$15)^3+D40/(1+$D$15)^4+D41/(1+$D$15)^5 -> 282.63726
A46: Terminal Value (Gordon Growth) | B46: =B41*(1+$B$25)/($B$15-$B$25) -> 6006.7178 | C46: =C41*(1+$C$25)/($C$15-$C$25) -> 3266.4636 | D46: =D41*(1+$D$25)/($D$15-$D$25) -> 1605.6115
...

Sheet Rule_of_40
A1: FSLY — RULE OF 40 ANALYSIS
A2: Rule of 40 = Revenue Growth % + Profitability Margin %. >40 healthy, >60 exceptional.
A4: FSLY SCORECARD — TREND
A5: Basis | B5: Growth % | C5: Margin % | D5: Rule of 40
A6: FY2025 — FCF margin | B6: 0.148 | C6: 0.073 | D6: =(B6+C6)*100 -> 22.1
A7: FY2025 — Adj. EBITDA margin | B7: 0.148 | C7: 0.124 | D7: =(B7+C7)*100 -> 27.2
A8: Q1 2026 — Adj. EBITDA margin | B8: 0.2 | C8: 0.17 | D8: =(B8+C8)*100 -> 37
A9: Q2 2026 — FCF margin (capex-heavy) | B9: 0.23 | C9: 0.02 | D9: =(B9+C9)*100 -> 25
A10: Q2 2026 — Non-GAAP op margin | B10: 0.23 | C10: 0.147 | D10: =(B10+C10)*100 -> 37.7
A11: Q2 2026 — Adj. EBITDA margin | B11: 0.23 | C11: 0.208 | D11: =(B11+C11)*100 -> 43.8
A12: FY2026 guided — Non-GAAP op margin | B12: 0.184 | C12: 0.124 | D12: =(B12+C12)*100 -> 30.8
A14: HEADLINES
A15: Q2 2026 headline R40 (adj. EBITDA basis) — FIRST CROSS ABOVE 40 | D15: =D11 -> 43.8
A16: FY2025 headline R40 (adj. EBITDA basis) | D16: =D7 -> 27.2
A17: Trend: 27.2 (FY25) → 37.0 (Q1'26) → 43.8 (Q2'26). The June 2026 memo called crossing 40 'the single most important fundamental milestone for a re-rating' — it happened this quarter, and the stock re-rated +38%.
A19: PEER COMPARABLES (CDN / Edge / Security)
A20: Company | B20: Ticker | C20: Fwd Rev Growth | D20: FCF Margin (est.) | E20: Rule of 40 | F20: Fwd EV/Sales | G20: Note
A21: Fastly | B21: FSLY | C21: 0.18 | D21: 0.08 | E21: =(C21+D21)*100 -> 26 | F21: 6 | G21: Subject — Ro40 crossed on EBITDA basis; EV/S re-rated 4.4x→6.0x since June
A22: Cloudflare | B22: NET | C22: 0.29 | D22: 0.12 | E22: =(C22+D22)*100 -> 41 | F22: 26 | G22: Premium multiple; ~30% growth
A23: Akamai | B23: AKAM | C23: 0.06 | D23: 0.22 | E23: =(C23+D23)*100 -> 28 | F23: 4.3 | G23: Mature; security/compute pivot
A24: Datadog | B24: DDOG | C24: 0.23 | D24: 0.26 | E24: =(C24+D24)*100 -> 49 | F24: 13 | G24: Observability; high R40
A25: Cloudflare-tier avg | B25: — | C25: 0.29 | D25: 0.12 | E25: =(C25+D25)*100 -> 41 | F25: 26 | G25: Hypergrowth comp
A26: CDN/infra avg | B26: — | C26: 0.1 | D26: 0.18 | E26: =(C26+D26)*100 -> 28 | F26: 4 | G26: Mature infra comp
A27: Limelight/Edgio (defunct) | B27: — | C27: n/a | D27: n/a | E27: n/a | F27: n/a | G27: Cautionary CDN comp — went to zero
A29: Peer growth/FCF figures are approximate analyst estimates for context, not precise consensus.
A32: LEADERSHIP & GOVERNANCE SCORECARD (0/5/10 per criterion, max 50)
A33: CEO: Kip Compton (hired; internal promotion from Chief Product Officer, June 2025; ex-Cisco SVP)
A34: CFO: Richard Wong (Aug 2025; first CFO at Benchling and Houzz; ex-VP Finance LinkedIn) | Insider ownership: 6.21% | Institutional: 86.45%
A36: Criterion | B36: Score | C36: Evidence
A37: Execution track record | B37: 10 | C37: Two consecutive beat-and-raise quarters under new team; FY26 op income guide raised 46% ($63M→$92M mid) on Aug 5 2026
A38: Founder / tenure / skin in game | B38: 5 | C38: Hired CEO, 14-month tenure; founder Bergman no longer in executive seat; insider ownership 6.21% (modest)
A39: Capital allocation | B39: 5 | C39: Converts managed, no dilutive M&A; but diluted count 176.5M→180.3M in 2 qtrs + new universal shelf filed Aug 2026 (dilution overhang)
A40: Insider activity (Form 4) | B40: 5 | C40: Routine plan/tax sells only (CEO sold 14,868 sh Aug 2026; CTO tax sells; director 10b5-1); zero open-market buys in last 12 mo
A41: Governance & alignment | B41: 5 | C41: Orderly succession but heavy C-suite turnover (CEO, CFO, PAO changed within ~14 months); high board independence
A42: COMPOSITE (max 50) | B42: =SUM(B37:B41) -> 30 | C42: =IF(B42>=40,"Strong — supports Bull Case",IF(B42>=25,"Neutral — not a differentiator","Risk — supports Bear Case")) -> Neutral — not a differentiator

Sheet Options_Strategy
A1: FSLY — OPTIONS OVERLAY (optional; existing long-share position)
A2: Vehicle this run: LONG EQUITY. Overlay is optional income/protection. Post-spike IV is elevated — favors SELLING premium, not buying. Yields PER CYCLE.
A4: MARKET REFERENCE
A5: Current Price | B5: =Dashboard!C6 -> 27.75
A6: 52-Week High (resistance) | B6: 34.82
A7: 50-Day SMA (support) | B7: 19.83
A8: 200-Day SMA (support) | B8: 17.22
A9: DCF Bull Case | B9: =Model!B52 -> 23.587221
A10: DCF Base Case | B10: =Model!C52 -> 13.368514
A11: DCF Bear Case | B11: =Model!D52 -> 6.9275071
A13: RECOMMENDED STRATEGIES (per 1 contract = 100 shares)
A14: Strategy | B14: Structure | C14: Net Premium / Cost | D14: Max Gain | E14: Max Loss / Risk | F14: Rationale
A15: Covered Call (primary) | B15: Sell ~$32 call, 45–60 DTE (Sep/Oct 2026) | C15: est. +$1.30–1.60 (~$130–160/contract) | D15: Premium + ~$4.25 appreciation to $32 ≈ $560–585/contract | E15: Caps upside above $32; keep shares unless called | F15: Price already exceeds bull DCF; $32 sits in the May-peak supply zone $32.36–34.82. Harvests post-spike IV. ~5% per-cycle yield.
A16: Collar (protective) | B16: Sell $32 call + buy $22 put, ~60 DTE | C16: ≈ net-zero cost (est.) | D16: Premium + appreciation to $32 | E16: Floored near $22 (gap-fill level / pre-earnings base) | F16: After a +21% single-day gap with RSI 70 and 18% short float, protecting the unrealized gain is cheap. Best structure if not trimming shares.
A17: Cash-Secured Put (re-entry) | B17: Sell ~$20 put, 45 DTE | C17: est. +$0.55–0.75 (~$55–75/contract) | D17: Premium kept if FSLY stays above $20 | E17: Assigned at $20 (net ~$19.35) — $2,000 cash/contract | F17: Re-accumulates near 50-day SMA ($19.83) if the gap fully fades. Note: still above base DCF ($12.87) — size modestly.
A19: Primary action this quarter is on the SHARES (hold core / trim into strength above bull DCF) — see memo Verdict. Overlay is optional.
A20: Premiums are estimates pending live IV; verify on the chain. Yields are PER CYCLE, not annualized. Not investment advice.
