Workbook

Sheet Dashboard
A1: SERVICENOW (NOW) — DASHBOARD | Q2 2026 Refresh vs. June 5, 2026
A2: Rating: BUY / ACCUMULATE (reaffirmed, higher conviction) • Vehicle: Long equity + cash-secured puts
A4: VALUATION SNAPSHOT — DCF (single WACC 11%)
A5: Scenario | B5: Intrinsic / Share | C5: vs Current | D5: Jun-5 Intrinsic | E5: Driver
A6: 🐂 Bull | B6: =NOW_Model!B37 -> 156.30803 | C6: =NOW_Model!B38 -> 0.56308028 | D6: 185.38 | E6: Growth reaccel + AI ACV >$1.5B; margin recovery to 42-44%
A7: ⚖️ Base | B7: =NOW_Model!B53 -> 127.68842 | C7: =NOW_Model!B54 -> 0.27688416 | D7: 128.46 | E7: Guide holds; FCF normalizes to ~40%; cRPO ~20%
A8: 🐻 Bear | B8: =NOW_Model!B69 -> 92.899305 | C8: =NOW_Model!B70 -> -0.071006949 | D8: 82.5 | E8: Growth to low-teens; MSFT/CRM pressure; margins stall
A10: KEY METRICS — NOW vs. JUNE
A11: Metric | B11: Q2 2026 | C11: Q1 2026 (Jun memo) | D11: Change
A12: Reference Price ($) | B12: =NOW_Model!B21 -> 100 | C12: 119.29 | D12: ▼ ~16% cheaper
A13: Total Revenue ($M, qtr) | B13: 3987 | C13: 3770 | D13: ▲ +$217M
A14: Total Rev Growth YoY | B14: =NOW_Model!D7 -> 0.24 | C14: 0.22 | D14: ▲ +2 pts
A15: cRPO ($M) | B15: 13200 | C15: 12640 | D15: ▲ +$560M
A16: cRPO Growth YoY | B16: 0.21 | C16: 0.225 | D16: ▼ -1.5 pts
A17: Non-GAAP Op Margin | B17: =NOW_Model!D10 -> 0.295 | C17: 0.32 | D17: ▼ -2.5 pts (deal costs)
A18: Net Cash / (Net Debt) ($M) | B18: =NOW_Model!B19 -> -810 | C18: 3691 | D18: ▼ to net debt
A19: ServiceNow AI ACV | B19: $1.0B+ | C19: ~$1B target | D19: ▲ crossed $1B
A20: Rule of 40 (FY, growth+FCF) | B20: 0.575 | C20: 0.575 | D20: → ~57 (Rule of 56)
A22: TECHNICAL LEVELS
A23: Reference Price | B23: ~$100 (post-print; 7/22 close $95.46)
A24: 52-Week Range | B24: $81.24 – $210.20
A25: 50-Day SMA | B25: ~$104
A26: 200-Day SMA | B26: ~$128 (≈ base-case DCF)
A27: Support | B27: $95 / $88 / $81 (52-wk low)
A28: Resistance | B28: $104 / $110 / $120 / $128

Sheet NOW_Model
A1: SERVICENOW (NOW) — Investment Model | Q2 2026 Refresh | 2026-07-23
A3: SECTION A — HISTORICAL & LATEST QUARTER
A4: Metric | B4: FY2025 | C4: Q1 2026 | D4: Q2 2026 | E4: YoY
A5: Subscription Revenue ($M) | B5: 12840 | C5: 3671 | D5: 3877
A6: Total Revenue ($M) | B6: 13285 | C6: 3770 | D6: 3987
A7: Total Revenue YoY Growth | B7: 0.21 | C7: 0.22 | D7: 0.24
A8: Subscription Rev YoY Growth | C8: 0.22 | D8: 0.245
A9: Non-GAAP Sub Gross Margin | C9: 0.815 | D9: 0.805
A10: Non-GAAP Operating Margin | C10: 0.32 | D10: 0.295
A11: Non-GAAP FCF Margin (qtr) | B11: 0.4 | C11: 0.44 | D11: 0.16
A12: cRPO ($M) | C12: 12640 | D12: 13200 | E12: 0.21
A13: Total RPO ($M) | C13: 27700 | D13: 29000 | E13: 0.21
A14: Non-GAAP Diluted EPS ($) | C14: 0.97 | D14: 0.9
A16: SECTION B — DCF INPUTS (shared across all scenarios)
A17: WACC — SINGLE discount rate (all scenarios) | B17: 0.11
A18: FY2026 Total Revenue base ($M) | B18: 16200
A19: Net Cash / (Net Debt) ($M) | B19: -810
A20: Diluted Shares Outstanding (M) | B20: 1034
A21: Current / Reference Price ($) | B21: 100
A23: 🐂 BULL SCENARIO — Projections & DCF
A24: Line | B24: FY2026 | C24: FY2027 | D24: FY2028 | E24: FY2029 | F24: FY2030
A25: Rev Growth (from FY2026 guide base) | B25: — | C25: 0.23 | D25: 0.2 | E25: 0.18 | F25: 0.16
A26: Revenue ($M) | B26: =$B$18 -> 16200 | C26: =B26*(1+C25) -> 19926 | D26: =C26*(1+D25) -> 23911.2 | E26: =D26*(1+E25) -> 28215.216 | F26: =E26*(1+F25) -> 32729.651
A27: FCF Margin | B27: 0.35 | C27: 0.4 | D27: 0.42 | E27: 0.43 | F27: 0.44
A28: Free Cash Flow ($M) | B28: =B26*B27 -> 5670 | C28: =C26*C27 -> 7970.4 | D28: =D26*D27 -> 10042.704 | E28: =E26*E27 -> 12132.543 | F28: =F26*F27 -> 14401.046
A29: PV of FCF ($M) | B29: =B28/(1+$B$17)^1 -> 5108.1081 | C29: =C28/(1+$B$17)^2 -> 6468.9554 | D29: =D28/(1+$B$17)^3 -> 7343.1386 | E29: =E28/(1+$B$17)^4 -> 7992.0818 | F29: =F28/(1+$B$17)^5 -> 8546.32
A30: Terminal Growth | B30: 0.04 | C30: Terminal FCF Margin | D30: 0.44
A31: Sum PV of FCF (Yr1-5) ($M) | B31: =SUM(B29:F29) -> 35458.604
A32: Terminal-Year FCF ($M) | B32: =F26*(1+B30)*D30 -> 14977.088
A33: Terminal Value (Gordon) ($M) | B33: =B32/($B$17-B30) -> 213958.4
A34: PV of Terminal Value ($M) | B34: =B33/(1+$B$17)^5 -> 126973.9
A35: Enterprise Value ($M) | B35: =B31+B34 -> 162432.5
A36: Equity Value ($M) [EV + Net Cash] | B36: =B35+$B$19 -> 161622.5
A37: INTRINSIC VALUE / SHARE ($) | B37: =B36/$B$20 -> 156.30803
A38: Upside/(Downside) vs Current | B38: =B37/$B$21-1 -> 0.56308028
A39: ⚖️ BASE SCENARIO — Projections & DCF
A40: Line | B40: FY2026 | C40: FY2027 | D40: FY2028 | E40: FY2029 | F40: FY2030
A41: Rev Growth (from FY2026 guide base) | B41: — | C41: 0.21 | D41: 0.18 | E41: 0.15 | F41: 0.13
A42: Revenue ($M) | B42: =$B$18 -> 16200 | C42: =B42*(1+C41) -> 19602 | D42: =C42*(1+D41) -> 23130.36 | E42: =D42*(1+E41) -> 26599.914 | F42: =E42*(1+F41) -> 30057.903
A43: FCF Margin | B43: 0.35 | C43: 0.37 | D43: 0.39 | E43: 0.4 | F43: 0.41
...

Sheet Rule_of_40
A1: RULE OF 40 & PEER COMPS — NOW Q2 2026
A3: RULE OF 40 SCORECARD
A4: Basis | B4: Rev Growth | C4: Profitability | D4: Rule of 40 | E4: Read
A5: FY2026 (sub growth + FCF margin) | B5: 0.225 | C5: 0.35 | D5: =(B5+C5)*100 -> 57.5 | E5: Healthy — 'Rule of 56'
A6: Q2 2026 (rev growth + non-GAAP op) | B6: 0.24 | C6: 0.295 | D6: =(B6+C6)*100 -> 53.5 | E6: Strong (53-54)
A7: Q2 2026 (rev growth + FCF, qtr) | B7: 0.24 | C7: 0.16 | D7: =(B7+C7)*100 -> 40 | E7: Seasonal FCF trough — ignore qtr
A9: Benchmark: >40 healthy · >60 exceptional. NOW FY basis ~57 with FCF margin at its M&A-integration trough (35%); normalization toward 40% margin => Rule ~62.
A11: PEER COMPARABLES (approximate, forward)
A12: Ticker | B12: Rev Growth | C12: FCF Margin | D12: Rule of 40 | E12: EV/Sales | F12: EV/FCF
A13: NOW | B13: 0.235 | C13: 0.35 | D13: =(B13+C13)*100 -> 58.5 | E13: 7.5 | F13: 21
A14: PLTR | B14: 0.63 | C14: 0.55 | D14: =(B14+C14)*100 -> 118 | E14: 42 | F14: 80
A15: CRM | B15: 0.09 | C15: 0.32 | D15: =(B15+C15)*100 -> 41 | E15: 6 | F15: 19
A16: SNOW | B16: 0.24 | C16: 0.2 | D16: =(B16+C16)*100 -> 44 | E16: 11 | F16: 50
A17: DDOG | B17: 0.23 | C17: 0.26 | D17: =(B17+C17)*100 -> 49 | E17: 13 | F17: 52
A18: CRWD | B18: 0.2 | C18: 0.28 | D18: =(B18+C18)*100 -> 48 | E18: 18 | F18: 66
A19: WDAY | B19: 0.13 | C19: 0.26 | D19: =(B19+C19)*100 -> 39 | E19: 5.5 | F19: 22
A21: NOW ~7.5x fwd EV/Sales is the cheapest high-quality SaaS name on a Rule-of-40-adjusted basis. Re-rate to 10x => ~$150/sh.

Sheet Options_Strategy
A1: OPTIONS STRATEGY — NOW (post Q2 2026)
A2: Setup: stock ~$100, base-case DCF ~$128 (28% below intrinsic), only ~7% above bear. Options implied ~6-12% earnings move already realized.
A4: MARKET REFERENCE
A5: Reference Price | B5: ~$100
A6: Base-case DCF | B6: ~$128 (+28%)
A7: Bull / Bear DCF | B7: ~$156 / ~$93
A8: 52-wk Range | B8: $81.24 – $210.20
A9: Post-earnings IV | B9: Elevated into print; expect crush
A11: RECOMMENDED STRATEGIES
A12: Strategy | B12: Structure | C12: Net Prem / Cost | D12: Max Gain / Loss | E12: Rationale
A13: Cash-secured put (build) | B13: Sell $90 put, 8-10 wks | C13: +$4–6 credit | D13: Assign @ ~$85 basis | E13: Enter ~11% below bear DCF; premium into post-earn IV
A14: Long call spread | B14: Buy $100 / sell $130 (Jan-27) | C14: ~$10–12 debit | D14: +$18 / −$12 | E14: Profitable before base DCF ($128); defined risk
A15: Covered call (holders) | B15: Sell $120 call, 6-8 wks | C15: +$3–5 credit | D15: Caps at $120 | E15: Income while below intrinsic; roll up if breached
A16: LEAP call (conviction) | B16: Buy Jan-28 $110 call | C16: ~$18–22 debit | D16: 3–5x if $150+ | E16: 19-mo runway on the recovery thesis
A18: Per-cycle yield (not annualized). Size so a bear-case $93 outcome stays within portfolio risk limits.
