Workbook

Sheet Dashboard
A1: INVESTMENT DASHBOARD — $PLTR | Q2 2026 Earnings Update | August 3, 2026
A3: Metric | B3: Value | C3: Notes / Source
A4: Company | B4: Palantir Technologies | C4: NASDAQ: PLTR
A5: Current Price ($) | B5: =PLTR_Model!$B$51 -> 137.88 | C5: After-hours Aug 3, 2026; close $125.65
A6: Market Cap ($B) | B6: =PLTR_Model!$B$51*PLTR_Model!$B$50/1000 -> 356.4198 | C6: Price × diluted shares
A7: Enterprise Value ($B) | B7: =(PLTR_Model!$B$51*PLTR_Model!$B$50-PLTR_Model!$B$48)/1000 -> 347.2198 | C7: Mkt cap − net cash
A8: Q2 2026 Revenue ($M) | B8: =PLTR_Model!$I$4 -> 1940 | C8: +93% YoY — beat guide $1,797–1,801M
A9: Q2 2026 Adj Op Margin | B9: =PLTR_Model!$I$6 -> 0.62
A10: Q2 2026 Adj FCF Margin | B10: =PLTR_Model!$I$8 -> 0.63 | C10: $1.22B quarterly FCF
A11: Rule of 40 (Q2 2026) | B11: =PLTR_Model!$D$97 -> 155 | C11: 93% growth + 62% adj op margin
A12: FY2026 Revenue Guide ($M) | B12: =PLTR_Model!$B$25 -> 8154 | C12: Raised from $7,656M (+6.5% raise) — +82% YoY
A13: FY2026 Adj FCF Guide ($M) | B13: 4600 | C13: Guide $4.5–4.7B midpoint (raised from $4.2–4.4B)
A14: Cash, No Debt ($M) | B14: =PLTR_Model!$B$48 -> 9200 | C14: $9.2B; debt-free
A15: EV / FY2026E Sales | B15: =(PLTR_Model!$B$51*PLTR_Model!$B$50-PLTR_Model!$B$48)/PLTR_Model!$B$25 -> 42.582757 | C15: On raised guidance
A16: EV / FY2027E Sales (base) | B16: =(PLTR_Model!$B$51*PLTR_Model!$B$50-PLTR_Model!$B$48)/PLTR_Model!$C$36 -> 26.285652 | C16: Base scenario FY2027 revenue
A17: DCF Intrinsic — Bull ($) | B17: =PLTR_Model!$B$64 -> 88.408646 | C17: Single 13% WACC
A18: DCF Intrinsic — Base ($) | B18: =PLTR_Model!$B$77 -> 56.965784 | C18: Single 13% WACC
A19: DCF Intrinsic — Bear ($) | B19: =PLTR_Model!$B$90 -> 34.183098 | C19: Single 13% WACC
A20: Price vs Bull DCF | B20: =(PLTR_Model!$B$51-PLTR_Model!$B$64)/PLTR_Model!$B$64 -> 0.55957597 | C20: (+) = premium to intrinsic
A21: Price vs Base DCF | B21: =(PLTR_Model!$B$51-PLTR_Model!$B$77)/PLTR_Model!$B$77 -> 1.4204003
A22: 52-Week High ($) | B22: 207.52 | C22: stockanalysis.com Aug 3, 2026
A23: 52-Week Low ($) | B23: 106.37
A24: 200-Day SMA ($) | B24: 153.72 | C24: As of Jul 29, 2026 — key overhead resistance
A25: RSI (14) pre-earnings | B25: 46.5 | C25: Jul 29, 2026
A26: Leadership Composite (of 50) | B26: =Rule_of_40!$B$32 -> 30 | C26: See Rule_of_40 sheet scorecard
A28: COLOR CODING
A29: Blue = hardcoded inputs (source in cell comment)
A30: Black = formulas
A31: Green = cross-sheet links
A32: Gold fill = key outputs

Sheet PLTR_Model
A1: PALANTIR TECHNOLOGIES ($PLTR) — Investment Analysis Model — Q2 2026 Update (Aug 3, 2026)
A2: SECTION A — HISTORICAL DATA (FY2024–Q2 2026)
A3: Metric | B3: FY2024 | C3: FY2025 | D3: Q1 2025 | E3: Q2 2025 | F3: Q3 2025 | G3: Q4 2025 | H3: Q1 2026 | I3: Q2 2026
A4: Revenue ($M) | B4: 2865 | C4: 4477 | D4: 883.9 | E4: 1004 | F4: 1181 | G4: 1408 | H4: 1632.6 | I4: 1940
A5: YoY Revenue Growth | C5: 0.563 | H5: 0.869 | I5: 0.93
A6: Adj. Operating Margin | B6: 0.36 | C6: 0.5 | H6: 0.6 | I6: 0.62
A7: GAAP Operating Margin | H7: 0.46 | I7: 0.47
A8: Adj. FCF Margin | H8: 0.57 | I8: 0.63
A9: GAAP Net Income ($M) | I9: 1060
A11: Revenue Segment Detail (Q2 2026)
A12: Metric | B12: Q2 2026 ($M) | C12: YoY Growth
A13: US Revenue ($M) | B13: 1570 | C13: 1.15
A14: US Commercial Revenue ($M) | B14: 764 | C14: 1.49
A15: US Government Revenue ($M) | B15: 809 | C15: 0.9
A16: International Revenue ($M) | B16: 370
A17: Total Commercial ($M) | B17: 945 | C17: 1.1
A18: Total Government ($M) | B18: 990 | C18: 0.79
A19: Total Customers | B19: 1049 | C19: 0.24
A20: Net Dollar Retention | B20: 1.57
A21: US Comm Remaining Deal Value ($M) | B21: 6240 | C21: 1.24
A22: Total TCV Closed ($M) | B22: 3370 | C22: 0.49
A24: SECTION B — REVENUE & FCF PROJECTIONS (FY2026–FY2030)
A25: FY2026 Revenue base = guidance midpoint ($M) [growth from $8,154M guidance base] | B25: 8154
A26: Year | B26: FY2026 | C26: FY2027 | D26: FY2028 | E26: FY2029 | F26: FY2030
A28: Bull Scenario
A29: Bull Rev Growth Assumption | B29: 0.821 | C29: 0.72 | D29: 0.62 | E29: 0.52 | F29: 0.42
A30: Bull Revenue ($M) | B30: =$B$25 -> 8154 | C30: =B30*(1+C29) -> 14024.88 | D30: =C30*(1+D29) -> 22720.306 | E30: =D30*(1+E29) -> 34534.865 | F30: =E30*(1+F29) -> 49039.508
A31: Bull FCF Margin Assumption | B31: 0.58 | C31: 0.6 | D31: 0.62 | E31: 0.62 | F31: 0.62
A32: Bull FCF ($M) | B32: =B30*B31 -> 4729.32 | C32: =C30*C31 -> 8414.928 | D32: =D30*D31 -> 14086.589 | E32: =E30*E31 -> 21411.616 | F32: =F30*F31 -> 30404.495
A34: Base Scenario
A35: Base Rev Growth Assumption | B35: 0.821 | C35: 0.62 | D35: 0.47 | E35: 0.37 | F35: 0.3
A36: Base Revenue ($M) | B36: =$B$25 -> 8154 | C36: =B36*(1+C35) -> 13209.48 | D36: =C36*(1+D35) -> 19417.936 | E36: =D36*(1+E35) -> 26602.572 | F36: =E36*(1+F35) -> 34583.343
A37: Base FCF Margin Assumption | B37: 0.56 | C37: 0.56 | D37: 0.55 | E37: 0.54 | F37: 0.52
A38: Base FCF ($M) | B38: =B36*B37 -> 4566.24 | C38: =C36*C37 -> 7397.3088 | D38: =D36*D37 -> 10679.865 | E38: =E36*E37 -> 14365.389 | F38: =F36*F37 -> 17983.339
A40: Bear Scenario
A41: Bear Rev Growth Assumption | B41: 0.821 | C41: 0.47 | D41: 0.32 | E41: 0.27 | F41: 0.22
A42: Bear Revenue ($M) | B42: =$B$25 -> 8154 | C42: =B42*(1+C41) -> 11986.38 | D42: =C42*(1+D41) -> 15822.022 | E42: =D42*(1+E41) -> 20093.967 | F42: =E42*(1+F41) -> 24514.64
A43: Bear FCF Margin Assumption | B43: 0.52 | C43: 0.5 | D43: 0.47 | E43: 0.44 | F43: 0.4
A44: Bear FCF ($M) | B44: =B42*B43 -> 4240.08 | C44: =C42*C43 -> 5993.19 | D44: =D42*D43 -> 7436.3502 | E44: =E42*E43 -> 8841.3457 | F44: =F42*F43 -> 9805.8561
A47: SECTION C — DCF VALUATION (SINGLE WACC = 13% ACROSS ALL SCENARIOS)
...

Sheet Rule_of_40
A1: RULE OF 40 + PEER COMPS + LEADERSHIP SCORECARD — $PLTR
A3: Rule of 40 Scorecard
A4: Period | B4: Rev Growth | C4: Adj Op Margin | D4: FCF Margin | E4: Ro40 (Op) | F4: Ro40 (FCF)
A5: FY2025 | B5: 0.56 | C5: 0.5 | D5: 0.5 | E5: =(B5+C5)*100 -> 106 | F5: =(B5+D5)*100 -> 106
A6: Q1 2026 | B6: 0.85 | C6: 0.6 | D6: 0.57 | E6: =(B6+C6)*100 -> 145 | F6: =(B6+D6)*100 -> 142
A7: Q2 2026 | B7: 0.93 | C7: 0.62 | D7: 0.63 | E7: =(B7+C7)*100 -> 155 | F7: =(B7+D7)*100 -> 156
A9: Benchmark: >40 healthy | >60 exceptional | >100 rare. Q2 2026 = 155 — a new company record.
A11: Peer Comparables (approximate, Aug 2026)
A12: Ticker | B12: Fwd Rev Growth | C12: FCF Margin | D12: Rule of 40 | E12: Fwd EV/Sales
A13: PLTR | B13: 0.82 | C13: 0.63 | D13: =(B13+C13)*100 -> 145 | E13: 42.6
A14: NOW | B14: 0.24 | C14: 0.35 | D14: =(B14+C14)*100 -> 59 | E14: 7
A15: CRM | B15: 0.09 | C15: 0.32 | D15: =(B15+C15)*100 -> 41 | E15: 6
A16: SNOW | B16: 0.23 | C16: 0.18 | D16: =(B16+C16)*100 -> 41 | E16: 10
A17: DDOG | B17: 0.23 | C17: 0.25 | D17: =(B17+C17)*100 -> 48 | E17: 13
A18: CRWD | B18: 0.2 | C18: 0.28 | D18: =(B18+C18)*100 -> 48 | E18: 19
A19: WDAY | B19: 0.13 | C19: 0.25 | D19: =(B19+C19)*100 -> 38 | E19: 6
A22: LEADERSHIP & GOVERNANCE SCORECARD (Nash-style, 0/5/10 per criterion)
A23: CEO: Alex Karp — co-founder, CEO since 2003 (23 yrs). Chairman: Peter Thiel (co-founder).
A24: Multi-class shares (A/B/F) — founders retain voting control via Class F structure.
A25: Criterion | B25: Score | C25: Evidence
A27: Execution track record | B27: 10 | C27: 8 straight beats; FY26 guide raised +10pp (Q1) then +6.5% again (Q2, Aug 3); 93% growth @ 62% adj op margin
A28: Founder / tenure / skin in game | B28: 10 | C28: Karp co-founder-CEO 23 yrs; Thiel chairman; founders retain large economic + voting stakes
A29: Capital allocation | B29: 5 | C29: $9.2B cash, zero debt, no dilutive M&A; but SBC ~12% of revenue and steady share-count creep
A30: Insider activity (Form 4) | B30: 0 | C30: $433M combined insider sales in 3 months pre-Q1'26 (Thiel ~$290M, Karp ~$132M/32 txns, Cohen ~$100M); zero open-market buys
A31: Governance & alignment | B31: 5 | C31: Class F super-voting entrenchment; elite execution partly offsets (founder-led hypergrowth adaptation)
A32: COMPOSITE (of 50) | B32: =SUM(B27:B31) -> 30 | C32: =IF(B32>=40,"Strong — feeds Bull",IF(B32>=25,"Neutral — acceptable","Risk — feeds Bear")) -> Neutral — acceptable
A33: FLAG: Score of 0 on Insider Activity — called out in memo regardless of composite (asymmetric governance risk).

Sheet Options_Strategy
A1: OPTIONS STRATEGY — $PLTR (overlay on existing long equity) — Aug 3, 2026
A3: Market Data Reference
A4: Price (after-hours 8/3) | B4: 137.88 | C4: Post-earnings +9.7%; close $125.65
A5: 52-Week Range | B5: 106.37 – 207.52
A6: 200-Day SMA | B6: 153.72 | C6: Key overhead resistance
A7: IV (pre-earnings, June ref) | B7: 0.688 | C7: IV crush expected T+1 — verify live before trading
A8: Earnings catalyst | B8: Q3 report ~Nov 2026 | C8: Next major IV event
A10: Recommended Strategies (holder of long shares)
A11: Strategy | B11: Structure | C11: Strikes | D11: Expiry | E11: Est. Premium | F11: Max Gain | G11: Max Loss | H11: Rationale
A12: Covered Call | B12: Sell 1 call / 100 sh | C12: $155–160 | D12: 6–8 wks | E12: $4–7/sh | F12: Strike − basis + prem | G12: Shares called away | H12: Strike sits at 200-day SMA resistance ($154). Sell into residual post-earnings IV before full crush.
A13: Protective Put | B13: Buy 1 put / 100 sh | C13: $115–120 | D13: Jan 2027 | E13: ($10–14)/sh | F13: Unlimited upside kept | G13: Premium paid | H13: Insurance for basis >$100. Price is ~57% above bull-case DCF ($88) — repricing risk is real.
A14: Collar | B14: CC + PP combined | C14: $160 C / $115 P | D14: Oct–Nov 2026 | E14: ~net flat | F14: Capped at $160 | G14: Floored at $115 | H14: Zero-cost band through next earnings; locks in the post-Q2 pop.
A15: CSP (add-only) | B15: Sell cash-secured put | C15: $110–115 | D15: 8–10 wks | E15: $5–8/sh | F15: Premium | G15: Assigned at strike | H15: Entry discipline: assignment basis ~$104–108 — near 52-wk low and closer to DCF territory.
A17: NOTE: All premium estimates pre-verification. PLTR options carry high risk (valuation + IV). Size appropriately.
