Workbook

Sheet Dashboard
A1: TRMB — INVESTMENT DASHBOARD
A2: Trimble Inc. (NASDAQ: TRMB) | Analyst: Ed | Date: 2026-06-11 | $ in millions unless noted
A4: Snapshot
A5: Current Price | B5: =Model!B4 -> 50
A6: Diluted Shares (M) | B6: =Model!B5 -> 235
A7: Market Cap ($M) | B7: =B5*B6 -> 11750
A8: Cash & Equivalents ($M) | B8: =Model!B6 -> 234.1
A9: Total Debt ($M) | B9: =Model!B7 -> 1412.8
A10: Net Debt ($M) | B10: =B9-B8 -> 1178.7
A11: Enterprise Value ($M) | B11: =B7+B10 -> 12928.7
A13: Operating Metrics (Q1 2026)
A14: Q1'26 Revenue ($M) | B14: 939.9
A15: Q1'26 Revenue Growth YoY | B15: 0.12
A16: ARR ($B) | B16: 2.435
A17: Recurring/Software % of Rev | B17: 0.78
A18: Non-GAAP Gross Margin | B18: 0.71
A19: Non-GAAP Operating Margin | B19: 0.259
A20: Adj. EBITDA Margin | B20: 0.274
A21: FY2026E Non-GAAP EPS (mid) | B21: 3.555
A23: Valuation Multiples
A24: EV / FY2026E Revenue | B24: =B11/Model!B52 -> 3.3390238
A25: Fwd P/E (Price / FY26E NG-EPS) | B25: =B5/B21 -> 14.064698
A26: EV / FY2026E Adj. EBITDA | B26: =B11/(Model!B52*0.274) -> 12.186218
A27: FCF Yield (FY26E FCF / Mkt Cap) | B27: =Model!B53/B7 -> 0.056020426
A29: Rule of 40 (hybrid SW/HW)
A30: Organic Growth + Non-GAAP Op Margin | B30: =0.12+0.259 -> 0.379
A31: Organic Growth + FCF Margin (FY26E) | B31: =0.1+Model!B54 -> 0.27
A33: DCF Intrinsic Value / Share (linked from Model)
A34: Scenario | B34: Bear | C34: Base | D34: Bull
A35: Intrinsic Price/Share | B35: =Model!B47 -> 35.970007 | C35: =Model!C47 -> 72.108218 | D35: =Model!D47 -> 96.753386
A36: Upside / (Downside) vs. Current | B36: =B35/$B$5-1 -> -0.28059985 | C36: =C35/$B$5-1 -> 0.44216436 | D36: =D35/$B$5-1 -> 0.93506773
A38: Technical Levels
A39: 52-Week High | B39: 87.5
A40: 52-Week Low | B40: 49.43
A41: 50-Day SMA (approx) | B41: 62
A42: 200-Day SMA (approx) | B42: 73
A43: RSI (14) | B43: 26
A44: IV Rank (elevated) | B44: 0.72
A45: Price below both SMAs — downtrend; RSI oversold (~26).

Sheet Model
A1: TRMB — DCF VALUATION MODEL (Single WACC across all scenarios)
A2: Trimble Inc. (NASDAQ: TRMB) | Analyst: Ed | Date: 2026-06-11 | $ in millions unless noted
A4: Current Price ($) | B4: 50
A5: Diluted Shares (M) | B5: 235
A6: Cash & Equivalents ($M) | B6: 234.1
A7: Total Debt ($M) | B7: 1412.8
A8: Net Debt ($M) | B8: =B7-B6 -> 1178.7
A9: WACC (single, all scenarios) | B9: 0.095
A10: FY2025E Revenue base ($M) | B10: 3520
A11: FY2026E Revenue (guid mid, $M) | B11: 3875
A13: Scenario Assumptions (Bull / Base / Bear share ONE WACC = B9)
A14: Assumption | B14: Bear | C14: Base | D14: Bull
A15: Rev Growth Yr1 (FY26) | B15: 0.07 | C15: 0.1 | D15: 0.11
A16: Rev Growth Yr2 (FY27) | B16: 0.05 | C16: 0.09 | D16: 0.11
A17: Rev Growth Yr3 (FY28) | B17: 0.04 | C17: 0.08 | D17: 0.1
A18: Rev Growth Yr4 (FY29) | B18: 0.04 | C18: 0.08 | D18: 0.1
A19: Rev Growth Yr5 (FY30) | B19: 0.03 | C19: 0.07 | D19: 0.09
A20: FCF Margin Yr1 | B20: 0.15 | C20: 0.17 | D20: 0.18
A21: FCF Margin Yr2 | B21: 0.155 | C21: 0.185 | D21: 0.2
A22: FCF Margin Yr3 | B22: 0.16 | C22: 0.2 | D22: 0.22
A23: FCF Margin Yr4 | B23: 0.165 | C23: 0.21 | D23: 0.235
A24: FCF Margin Yr5 (terminal) | B24: 0.17 | C24: 0.22 | D24: 0.25
A25: Terminal EV/FCF Multiple | B25: 15 | C25: 20 | D25: 22
A26: Terminal Growth (x-check) | B26: 0.025 | C26: 0.035 | D26: 0.04
A28: Revenue Projection ($M)
A29: Scenario | B29: FY26 | C29: FY27 | D29: FY28 | E29: FY29 | F29: FY30
A30: Bear | B30: =$B$10*(1+B15) -> 3766.4 | C30: =B30*(1+B16) -> 3954.72 | D30: =C30*(1+B17) -> 4112.9088 | E30: =D30*(1+B18) -> 4277.4252 | F30: =E30*(1+B19) -> 4405.7479
A31: Base | B31: =$B$10*(1+C15) -> 3872 | C31: =B31*(1+C16) -> 4220.48 | D31: =C31*(1+C17) -> 4558.1184 | E31: =D31*(1+C18) -> 4922.7679 | F31: =E31*(1+C19) -> 5267.3616
A32: Bull | B32: =$B$10*(1+D15) -> 3907.2 | C32: =B32*(1+D16) -> 4336.992 | D32: =C32*(1+D17) -> 4770.6912 | E32: =D32*(1+D18) -> 5247.7603 | F32: =E32*(1+D19) -> 5720.0587
A34: Free Cash Flow Projection ($M)
A35: Scenario | B35: FY26 | C35: FY27 | D35: FY28 | E35: FY29 | F35: FY30
A36: Bear | B36: =B30*B20 -> 564.96 | C36: =C30*B21 -> 612.9816 | D36: =D30*B22 -> 658.06541 | E36: =E30*B23 -> 705.77515 | F36: =F30*B24 -> 748.97714
A37: Base | B37: =B31*C20 -> 658.24 | C37: =C31*C21 -> 780.7888 | D37: =D31*C22 -> 911.62368 | E37: =E31*C23 -> 1033.7813 | F37: =F31*C24 -> 1158.8196
A38: Bull | B38: =B32*D20 -> 703.296 | C38: =C32*D21 -> 867.3984 | D38: =D32*D22 -> 1049.5521 | E38: =E32*D23 -> 1233.2237 | F38: =F32*D24 -> 1430.0147
A40: DCF Valuation Output
A41: Metric | B41: Bear | C41: Base | D41: Bull
A42: PV of Explicit FCF ($M) | B42: =B36/(1+$B$9)^1+C36/(1+$B$9)^2+D36/(1+$B$9)^3+E36/(1+$B$9)^4+F36/(1+$B$9)^5 -> 2495.0867 | C42: =B37/(1+$B$9)^1+C37/(1+$B$9)^2+D37/(1+$B$9)^3+E37/(1+$B$9)^4+F37/(1+$B$9)^5 -> 3401.8464 | D42: =B38/(1+$B$9)^1+C38/(1+$B$9)^2+D38/(1+$B$9)^3+E38/(1+$B$9)^4+F38/(1+$B$9)^5 -> 3931.2782
A43: Terminal Value ($M) | B43: =F36*B25 -> 11234.657 | C43: =F37*C25 -> 23176.391 | D43: =F38*D25 -> 31460.323
A44: PV of Terminal Value ($M) | B44: =B43/(1+$B$9)^5 -> 7136.565 | C44: =C43/(1+$B$9)^5 -> 14722.285 | D44: =D43/(1+$B$9)^5 -> 19984.468
A45: Enterprise Value ($M) | B45: =B42+B44 -> 9631.6517 | C45: =C42+C44 -> 18124.131 | D45: =D42+D44 -> 23915.746
...

Sheet Rule_of_40
A1: TRMB — RULE OF 40 & PEER COMPARABLES
A2: Trimble Inc. (NASDAQ: TRMB) | Analyst: Ed | Date: 2026-06-11 | $ in millions unless noted
A4: Rule of 40 Scorecard (hybrid software/hardware)
A5: Basis | B5: Growth % | C5: Profit % | D5: Rule of 40 | E5: Verdict
A6: Q1'26 ARR organic + NG Op Margin | B6: 0.12 | C6: 0.259 | D6: =B6+C6 -> 0.379 | E6: Healthy (~38)
A7: Q1'26 Rev growth + Adj EBITDA margin | B7: 0.12 | C7: 0.274 | D7: =B7+C7 -> 0.394 | E7: Healthy (~39)
A8: FY26E Rev growth + FCF margin | B8: 0.1 | C8: 0.175 | D8: =B8+C8 -> 0.275 | E8: Below 40 (~28)
A10: Segment Mix — Q1 2026
A11: Segment | B11: Q1'26 Rev ($M) | C11: YoY Growth | D11: % of Total
A12: AECO (Arch/Eng/Construction) | B12: 391.1 | C12: 0.166 | D12: =B12/SUM($B$12:$B$14) -> 0.4161081
A13: Field Systems | B13: 409.2 | C13: 0.139 | D13: =B13/SUM($B$12:$B$14) -> 0.43536546
A14: Transport & Logistics | B14: 139.6 | C14: -0.044 | D14: =B14/SUM($B$12:$B$14) -> 0.14852644
A15: Total | B15: =SUM(B12:B14) -> 939.9
A17: Peer Comparables (approximate — relative context only)
A18: Company | B18: Ticker | C18: Fwd Rev Gr | D18: FCF Margin | E18: Rule of 40 | F18: Fwd EV/Sales | G18: Note
A19: Trimble | B19: TRMB | C19: 0.1 | D19: 0.175 | E19: =C19+D19 -> 0.275 | F19: 3.3 | G19: Subject — 78% recurring
A20: Hexagon AB | B20: HXGBY | C20: 0.06 | D20: 0.2 | E20: =C20+D20 -> 0.26 | F20: 4.5 | G20: Closest geospatial peer
A21: AGCO | B21: AGCO | C21: 0.02 | D21: 0.07 | E21: =C21+D21 -> 0.09 | F21: 1.1 | G21: Ag/precision, cyclical
A22: Topcon | B22: 7732.T | C22: 0.05 | D22: 0.08 | E22: =C22+D22 -> 0.13 | F22: 1.3 | G22: Positioning/medical
A23: Bentley Systems | B23: BSY | C23: 0.11 | D23: 0.27 | E23: =C23+D23 -> 0.38 | F23: 9.5 | G23: Infra software pure-play
A24: Autodesk | B24: ADSK | C24: 0.11 | D24: 0.3 | E24: =C24+D24 -> 0.41 | F24: 8 | G24: Design software
A25: Zebra Tech | B25: ZBRA | C25: 0.06 | D25: 0.13 | E25: =C25+D25 -> 0.19 | F25: 2.8 | G25: Enterprise HW+SW
A26: TRMB trades at a discount to software-pure peers (BSY/ADSK) despite 78% recurring revenue; closer to hardware-blend peers.

Sheet Options_Strategy
A1: TRMB — OPTIONS STRATEGY OVERLAY (Long-Equity Initiation)
A2: Trimble Inc. (NASDAQ: TRMB) | Analyst: Ed | Date: 2026-06-11 | $ in millions unless noted
A4: Market Reference
A5: Current Price | B5: 50
A6: DCF Base Intrinsic | B6: 72
A7: DCF Bear | B7: 36
A8: 52-wk Low / High | B8: $49.43 / $87.50
A9: RSI (14) | B9: 26
A10: IV Rank (elevated) | B10: 0.72
A12: Recommended Structures (elevated IV → favor SELLING premium to enter)
A13: Strategy | B13: Structure | C13: Est. Prem/Debit | D13: Max Gain | E13: Max Loss | F13: Rationale
A14: Cash-Secured Put (initiate) | B14: Sell $45 put, ~60 DTE | C14: ~$2.00 cr ($200) | D14: $200 (4.4%/cycle) | E14: $4,300 if→0 | F14: High IV pays you to wait; net entry ~$43 vs DCF base $72
A15: CSP — deeper/safer | B15: Sell $42.50 put, ~60 DTE | C15: ~$1.40 cr ($140) | D15: $140 (3.3%/cycle) | E15: $4,110 | F15: Below 52-wk low entry; collect premium during downtrend
A16: Long LEAP (leveraged) | B16: Buy $50 call, Jan-2027 | C16: ~$6.50 debit ($650) | D16: Unbounded | E16: $650 | F16: Multi-quarter re-rate to DCF base $72; time the thesis
A17: Covered Call (post-assign) | B17: Sell $60 call, ~45 DTE | C17: prem + to $60 | D17: capped @ $60 | E17: own shares | F17: Harvest IV above cost once long shares
A19: Per-cycle yields, NOT annualized. Size so the bear-case ($36) outcome does not cause unacceptable portfolio loss. Not financial advice.
