Workbook

Sheet Dashboard
A1: DUTCH BROS ($BROS) — DASHBOARD — 2026-09-28
A2: Quarterly update (Phase 0B) of the 2026-08-10 analysis. Blue = hardcoded inputs, black = formulas, green = cross-sheet links.
A4: MARKET DATA
A5: Current price (Sep 25, 2026 close) | B5: 37.89
A6: 52-week high / low | B6: $74.02 / $37.72
A7: Fully exchanged diluted shares (M) | B7: 180
A8: Market cap ($M) | B8: =B5*B7
A9: Net cash ($M) | B9: 74
A10: Enterprise value ($M) | B10: =B8-B9
A11: EV / FY2026E EBITDA ($387.5M guide mid) | B11: =B10/387.5
A12: Short interest (% of float) | B12: 0.1261
A13: Q2 2026 ACTUALS (8-K, Aug 5 2026)
A14: Revenue ($M) | B14: 550.9
A15: Revenue growth YoY | B15: 0.325
A16: Systemwide SSS | B16: 0.058
A17: Systemwide transaction growth | B17: 0.017
A18: Co-op shop contribution margin | B18: 0.306
A19: Adj. EBITDA ($M) | B19: 113.7
A20: Adj. EPS (fully exchanged) | B20: 0.33
A21: Total shops (period end) | B21: 1225
A23: FY2026 GUIDANCE (RAISED AUG 5)
A24: Revenue | B24: $2.10–$2.13B (was $2.05–$2.08B)
A25: Systemwide SSS | B25: 5–6%
A26: Adj. EBITDA | B26: $385–$390M (was $370–$380M)
A27: Capex | B27: $350–$370M
A28: System shop openings | B28: ≥185
A30: DCF INTRINSIC VALUE (EBITDA-TERMINAL, 12% WACC)
A31: Scenario | B31: Bear | C31: Base | D31: Bull
A32: Intrinsic price / share | B32: =BROS_Model!B38 | C32: =BROS_Model!B64 | D32: =BROS_Model!B90
A33: vs current price | B33: =B32/$B$5-1 | C33: =C32/$B$5-1 | D33: =D32/$B$5-1
A36: TECHNICAL SNAPSHOT (own calc, Yahoo closes to Sep 25, 2026)
A37: 20-day SMA | B37: 43.23
A38: 50-day SMA | B38: 51.88
A39: 200-day SMA | B39: 56.13
A40: RSI (14) | B40: 20.8
A41: Support | B41: $37.72, then $34–35, then $30–31
A42: Resistance | B42: $40–41, then $43.23 (20d), $44.58

Sheet BROS_Model
A1: DUTCH BROS ($BROS) — DCF MODEL (EBITDA-TERMINAL METHOD) — 2026-09-28
A2: Single 12% WACC across all scenarios. Terminal EV/EBITDA calibrated to terminal EBITDA margin. Restaurant methodology. DCF inputs and Aug 2026 valuation date carried unchanged from the 2026-08-10 model (no new quarter or guidance).
A4: GLOBAL INPUTS (blue = hardcoded)
A5: FY2026 Revenue — guidance midpoint ($M) | B5: 2115
A6: FY2026 Adj. EBITDA — guidance midpoint ($M) | B6: 387.5
A7: WACC (single rate, all scenarios) | B7: 0.12
A8: Net cash ($M) | B8: 74
A9: Fully exchanged diluted shares (M) | B9: 180
A10: Years to terminal (FY2030 year-end) | B10: 4.4
A11: Cash taxes (% of EBITDA, simplification) | B11: 0.15
A12: Capex % of revenue — FY2026 | B12: 0.17
A13: Capex % of revenue — FY2030 (glide) | B13: 0.1
A15: BEAR CASE — SSS decelerates to 2–3%, traffic goes negative, margins compress; openings slow
A16: Revenue CAGR FY26→FY30 | B16: 0.12
A17: Terminal EBITDA margin (FY2030) | B17: 0.18
A18: Terminal EV/EBITDA multiple | B18: 12
A20: Projection ($M) | C20: 2026 | D20: 2027 | E20: 2028 | F20: 2029 | G20: 2030
A21: Revenue | C21: =$B$5 | D21: =C21*(1+$B$16) | E21: =D21*(1+$B$16) | F21: =E21*(1+$B$16) | G21: =F21*(1+$B$16)
A22: EBITDA margin % | C22: =$B$6/$B$5 | D22: =$B$6/$B$5+($B$17-$B$6/$B$5)*1/4 | E22: =$B$6/$B$5+($B$17-$B$6/$B$5)*2/4 | F22: =$B$6/$B$5+($B$17-$B$6/$B$5)*3/4 | G22: =$B$6/$B$5+($B$17-$B$6/$B$5)*4/4
A23: EBITDA | C23: =C21*C22 | D23: =D21*D22 | E23: =E21*E22 | F23: =F21*F22 | G23: =G21*G22
A24: Capex % rev | C24: =$B$12+($B$13-$B$12)*0/4 | D24: =$B$12+($B$13-$B$12)*1/4 | E24: =$B$12+($B$13-$B$12)*2/4 | F24: =$B$12+($B$13-$B$12)*3/4 | G24: =$B$12+($B$13-$B$12)*4/4
A25: Capex | C25: =C21*C24 | D25: =D21*D24 | E25: =E21*E24 | F25: =F21*F24 | G25: =G21*G24
A26: Cash taxes | C26: =C23*$B$11 | D26: =D23*$B$11 | E26: =E23*$B$11 | F26: =F23*$B$11 | G26: =G23*$B$11
A27: FCF | C27: =C23-C25-C26 | D27: =D23-D25-D26 | E27: =E23-E25-E26 | F27: =F23-F25-F26 | G27: =G23-G25-G26
A28: Discount factor | C28: 0 | D28: =1/(1+$B$7)^(1+0.4) | E28: =1/(1+$B$7)^(2+0.4) | F28: =1/(1+$B$7)^(3+0.4) | G28: =1/(1+$B$7)^(4+0.4)
A29: PV of FCF | C29: =C27*C28 | D29: =D27*D28 | E29: =E27*E28 | F29: =F27*F28 | G29: =G27*G28
A31: Terminal EV (FY30 EBITDA × multiple) ($M) | B31: =G23*$B$18
A32: PV of Terminal Value ($M) | B32: =G23*$B$18/(1+$B$7)^$B$10
A33: PV of interim FCF FY27–FY30 ($M) | B33: =SUM(D29:G29)
A34: Enterprise Value ($M) | B34: =B32+B33
A35: + Net cash ($M) | B35: =$B$8
A36: Equity Value ($M) | B36: =B34+B35
A37: ÷ Fully exchanged diluted shares (M) | B37: =$B$9
A38: INTRINSIC PRICE / SHARE | B38: =B36/B37
A41: BASE CASE — 18–20% revenue growth; SSS normalizes 4–5%; margins expand to 22% by FY2030
A42: Revenue CAGR FY26→FY30 | B42: 0.185
A43: Terminal EBITDA margin (FY2030) | B43: 0.22
A44: Terminal EV/EBITDA multiple | B44: 18
A46: Projection ($M) | C46: 2026 | D46: 2027 | E46: 2028 | F46: 2029 | G46: 2030
A47: Revenue | C47: =$B$5 | D47: =C47*(1+$B$42) | E47: =D47*(1+$B$42) | F47: =E47*(1+$B$42) | G47: =F47*(1+$B$42)
...

Sheet Unit_Economics
A1: UNIT ECONOMICS + PEER COMPS + LEADERSHIP SCORECARD
A2: Restaurant methodology — Rule of 40 replaced by unit-economics scorecard (see non-SaaS adaptations).
A4: UNIT ECONOMICS SCORECARD (Q2 2026)
A5: Metric | B5: Value | C5: Watch
A6: Systemwide SSS | B6: +5.8% | C6: Q3 guide 4–5% = deceleration
A7: System transaction growth | B7: +1.7% | C7: ALERT if negative — was +3.7% PY
A8: Avg ticket growth | B8: +4.1% | C8: Pricing contribution <1% in H2'26
A9: Co-op contribution margin | B9: 30.6% | C9: vs 31.1% PY; coffee + occupancy pressure
A10: Adj. EBITDA margin | B10: 20.6% | C10: vs 21.4% PY
A11: Net new shops (Q2 / H1) | B11: 48 / 89 | C11: On track for ≥185 FY26
A12: Total shops | B12: 1,225 of 4,000+ potential | C12: ~31% penetration; 2,029-shop 2029 goal, ~90% pipeline secured
A13: Est. AUV (systemwide) | B13: ~$2.2M (est.) | C13: Q1'26 was $2.16M +6.6% YoY
A16: PEER COMPARABLES (approximate, Aug 2026)
A17: Company | B17: Ticker | C17: SSS % | D17: RL margin % | E17: EV/EBITDA (fwd) | F17: Rev growth (fwd) | G17: Note
A18: Dutch Bros | B18: BROS | C18: +5.8% | D18: ~31% | E18: ~24x | F18: ~25–28% | G18: Subject — fastest grower in set
A19: Starbucks | B19: SBUX | C19: ~+1–3% | D19: n/a | E19: ~16–18x | F19: ~3–5% | G19: Scale leader, traffic-challenged
A20: Chipotle | B20: CMG | C20: ~+2–4% | D20: ~26–27% | E20: ~24–27x | F20: ~10–12% | G20: Margin benchmark
A21: CAVA | B21: CAVA | C21: ~+5–8% | D21: ~25% | E21: ~40x+ | F21: ~20–25% | G21: Closest growth comp, richer multiple
A22: Shake Shack | B22: SHAK | C22: ~+2–4% | D22: ~21–22% | E22: ~22–26x | F22: ~12–15% | G22: Mid-growth fast casual
A23: Wingstop | B23: WING | C23: ~flat–+3% | D23: n/a (franchise) | E23: ~38–45x | F23: ~15–20% | G23: Franchise model premium
A24: 7 Brew | B24: Private | C24: n/a | D24: n/a | E24: n/a | F24: Rapid | G24: Most direct competitor; won 73 Salad and Go sites for $143.2M (Sep 1, 2026 auction)
A25: Peer figures are approximate (Aug 2026 web sources; not refreshed in the Sep 28 update); directional context only.
A27: LEADERSHIP SCORECARD (Nash-style, 0/5/10 — evidence required)
A28: CEO: Christine Barone (hired, since Jan 2024; ex-Starbucks SVP, ex-True Food Kitchen CEO)
A29: Founder: Travis Boersma, Executive Chairman — 38.8% economic / 73.1% voting (Class B 10:1 super-vote)
A31: Criterion | B31: Score (0/5/10) | C31: Evidence
A32: Execution track record | B32: 10 | C32: Q2'26 beat; FY26 rev guide raised to $2.10–2.13B and EBITDA to $385–390M; 32.5% rev growth; 89 H1 openings on ≥185 pace
A33: Founder / tenure / skin in game | B33: 5 | C33: Founder Exec Chairman w/ 38.8% economic stake; but hired CEO tenure ~2.7 yrs (Sep 2026); founder in programmatic sell-down
A34: Capital allocation | B34: 5 | C34: Clutch $20M/20 sites; Salad and Go $105M stalking-horse bid — declined to counter 7 Brew's $143.2M (Sep 2026): price discipline, but 65 sites lost; capex $350–370M, negative FCF, no buybacks
A35: Insider activity (Form 4) | B35: 5 | C35: Director Todd Penegor bought 2,000 sh open-market @$51.56 (Aug 13, 2026) — first open-market buy found in 12 months; offsets little vs chair-linked 10b5-1 sales of 2.25M sh H1'26 @$60–64; no sales filed Aug 10–Sep 28
A36: Governance & alignment | B36: 5 | C36: Dual-class: Boersma 73.1% votes vs 38.8% economics (Class B 10 votes/sh, sunset <5%); separate CEO/Chair; no restatements
A37: COMPOSITE (max 50) | B37: =SUM(B32:B36) | C37: =IF(B37>=40,"Strong — feeds Bull Case",IF(B37>=25,"Neutral — not a differentiator","Risk — feeds Bear Case"))

Sheet Options_Strategy
A1: OPTIONS STRATEGY — LONG EQUITY HOLDER OVERLAY (Sep 28, 2026)
A3: MARKET DATA REFERENCE
A4: Current price | B4: 37.89
A5: 30-day implied volatility | B5: 0.3329
A6: DCF base (model) | B6: =BROS_Model!B64
A7: DCF bear (model) | B7: =BROS_Model!B38
A8: Support / Resistance | B8: $37.72, $34–35 / $40–41, $43–45
A9: Risk-free rate | B9: 0.04
A10: BLACK-SCHOLES PRICER (European, no dividends; days from Sep 28, 2026)
A11: Leg | B11: Strike ($) | C11: Days | D11: Type | E11: d1 | F11: d2 | G11: Premium est. ($/sh)
A12: CSP — sell Nov 20 $35 put | B12: 35 | C12: 53 | D12: Put | E12: =(LN($B$4/B12)+($B$9+$B$5^2/2)*(C12/365))/($B$5*SQRT(C12/365)) | F12: =E12-$B$5*SQRT(C12/365) | G12: =IF(D12="Call",$B$4*NORMSDIST(E12)-B12*EXP(-$B$9*C12/365)*NORMSDIST(F12),B12*EXP(-$B$9*C12/365)*NORMSDIST(-F12)-$B$4*NORMSDIST(-E12))
A13: CSP ladder — sell Dec 18 $32.5 put | B13: 32.5 | C13: 81 | D13: Put | E13: =(LN($B$4/B13)+($B$9+$B$5^2/2)*(C13/365))/($B$5*SQRT(C13/365)) | F13: =E13-$B$5*SQRT(C13/365) | G13: =IF(D13="Call",$B$4*NORMSDIST(E13)-B13*EXP(-$B$9*C13/365)*NORMSDIST(F13),B13*EXP(-$B$9*C13/365)*NORMSDIST(-F13)-$B$4*NORMSDIST(-E13))
A14: Covered call — sell Nov 20 $45 call | B14: 45 | C14: 53 | D14: Call | E14: =(LN($B$4/B14)+($B$9+$B$5^2/2)*(C14/365))/($B$5*SQRT(C14/365)) | F14: =E14-$B$5*SQRT(C14/365) | G14: =IF(D14="Call",$B$4*NORMSDIST(E14)-B14*EXP(-$B$9*C14/365)*NORMSDIST(F14),B14*EXP(-$B$9*C14/365)*NORMSDIST(-F14)-$B$4*NORMSDIST(-E14))
A17: RECOMMENDED STRATEGIES (Black-Scholes estimates at 33% IV — verify live)
A18: Strategy | B18: Premium $/sh | C18: Per-cycle yield | D18: Effective entry / cap | E18: Max loss $/contract | F18: Max gain | G18: Rationale
A19: CSP (accumulate, final tranche) | B19: =G12 | C19: =G12/B12 | D19: =B12-G12 | E19: =(B12-G12)*100 | F19: Premium if >$35 | G19: Strike at mid-2024 support; assignment ~$34.31 = 42% below DCF base, 32% above bear. Spans the Nov 4 print.
A20: CSP ladder (only if sized for bear) | B20: =G13 | C20: =G13/B13 | D20: =B13-G13 | E20: =(B13-G13)*100 | F20: Premium if >$32.5 | G20: Deeper entry near the Aug–Sep 2024 base; low IV makes the premium thin.
A21: Covered call (on a bounce only) | B21: =G14 | C21: =G14/B4 | D21: =B14 | E21: Shares called away above $45 | F21: Premium + move to $45 | G21: Strike at the old 52-wk low / gap resistance; writing it at $38 caps the recovery the thesis needs.
A23: Sizing rule: compute max loss in dollars before sizing. Bear-case DCF is ~$26 — size so a move there is acceptable. Yields are per-cycle, not annualized. Any $47.5 puts from the Aug 10 plan are in the money at $37.89.

Sheet Sentiment
A1: SOCIAL SENTIMENT — Stocktwits (data layer, not an edge)
A2: Context only. Never an input to the valuation, scenario weights, rating or options strikes. 2026-09 calibration (7 tickers): sentiment moves with price the same day and predicted nothing over the next 1–20 sessions.
A3: Symbol BROS · pulled 2026-09-28T07:31:00-07:00 · last bucket 2026-09-28 (provisional — Stocktwits revises the newest buckets)
A5: SNAPSHOT (used in the memo)
A6: Sentiment score (0–100) | B6: 61
A7: Band | B7: Slightly Bullish
A8: Change over 20 sessions (pts) | B8: 22
A9: Message volume (0–100) | B9: 54
A10: Watchers | B10: 12304
A12: REFERENCE ONLY — not used in the memo
A13: Percentile vs past year (weekly) | B13: 74 | E13: Flags: Divergence over 20 sessions: price down, crowd warming.; Concentrated stream: one author wrote 20% of recent posts.
A14: Change over 5 sessions (pts) | B14: -27 | E14: Notes: Pulse score 61 differs from last daily bucket 62 (2026-09-28).; Pulled before the 16:00 ET close: the pull-day price bar was dropped (unfinished session).
A15: Price return, 5 sessions | B15: -0.0535
A16: Price return, 20 sessions | B16: -0.2528
A17: Price vs crowd, 20 sessions | B17: price down, crowd warming
A18: Crowding flag | B18: none
A19: Chatter spikes (volume >= 75) in 3 months | B19: 2
A20: Recent posts sampled | B20: 30
A21: Unique authors | B21: 18
A22: Share of posts tagging 4+ tickers | B22: 0.067
A23: Top author's share of posts | B23: 0.2
A24: Share of posts with a Bullish/Bearish tag | B24: 0.333
A26: 3-MONTH DAILY SERIES
A27: Date | B27: Sentiment (0–100) | C27: Volume (0–100) | D27: Close ($)
A28: 2026-06-29 | B28: 44 | C28: 50 | D28: 71.69
A29: 2026-06-30 | B29: 47 | C29: 49 | D29: 71.81
A30: 2026-07-01 | B30: 48 | C30: 49 | D30: 73.31
A31: 2026-07-02 | B31: 49 | C31: 49 | D31: 72.16
A32: 2026-07-06 | B32: 41 | C32: 38 | D32: 68.09
A33: 2026-07-07 | B33: 37 | C33: 40 | D33: 66.28
A34: 2026-07-08 | B34: 34 | C34: 41 | D34: 64.93
A35: 2026-07-09 | B35: 35 | C35: 40 | D35: 65.64
A36: 2026-07-10 | B36: 35 | C36: 38 | D36: 67.56
A37: 2026-07-13 | B37: 29 | C37: 38 | D37: 66.46
A38: 2026-07-14 | B38: 31 | C38: 35 | D38: 64.05
A39: 2026-07-15 | B39: 34 | C39: 33 | D39: 63.86
... A91: 2026-09-28 | B91: 62 | C91: 54 | D91: 38.07
