Workbook

Sheet Dashboard
B2: FASTLY, INC. (NASDAQ: FSLY) — INVESTMENT DASHBOARD
B3: Analysis date: June 8, 2026 | Analyst: Ed | Rating: HOLD / Accumulate on weakness | Vehicle: Long equity + income options overlay
B5: MARKET SNAPSHOT
B6: Current Price | C6: 20.09 | E6: VALUATION SUMMARY
B7: 52-Week Range | C7: $6.29 – $34.82 | E7: DCF Bull Case / share | F7: =Model!C40 -> 24.161294
B8: Shares Outstanding (Class A, M) | C8: 156.4 | E8: DCF Base Case / share | F8: =Model!D40 -> 12.548002
B9: Diluted Shares — valuation (M) | C9: 165 | E9: DCF Bear Case / share | F9: =Model!E40 -> 6.9721529
B10: Market Cap ($M) | C10: =C6*C8 -> 3142.076 | E10: Current Price | F10: =C6 -> 20.09
B11: Cash + Marketable Securities ($M) | C11: 330.489 | E11: Base Case vs Current | F11: =F8/F10-1 -> -0.37541054
B12: Total Debt — convertible notes ($M) | C12: 323.62 | E12: FY2026 Guided Revenue ($M) | F12: 717.5
B13: Net Cash ($M) | C13: =C11-C12 -> 6.869 | E13: FY2026 Rev Growth (guidance) | F13: =F12/Model!B7-1 -> 0.14980658
B14: Enterprise Value ($M) | C14: =C10-C13 -> 3135.207 | E14: EV / FY26 Revenue | F14: =C14/F12 -> 4.3696265
E15: Rule of 40 (FY2025) | F15: =Rule_of_40!C9 -> 27.2
B16: FUNDAMENTALS (Most Recent Quarter — Q1 2026) | E16: Rule of 40 (Q1 2026 ann.) | F16: =Rule_of_40!C16 -> 37
B17: Q1 2026 Revenue ($M) | C17: 173.021
B18: Revenue Growth (YoY) | C18: 0.2 | E18: TECHNICAL LEVELS
B19: Security Revenue Growth (YoY) | C19: 0.47 | E19: 20-Day SMA (est.) | F19: 21.2
B20: GAAP Gross Margin | C20: 0.625 | E20: 50-Day SMA | F20: 23.34
B21: Non-GAAP Gross Margin | C21: 0.651 | E21: 200-Day SMA | F21: 17.14
B22: Non-GAAP Operating Margin | C22: 0.111 | E22: RSI (14, est.) | F22: 41
B23: Adj. EBITDA Margin | C23: 0.17 | E23: Implied Volatility (est.) | F23: Elevated
B24: FCF Margin (Q1 — heavy capex) | C24: 0.024
B25: LTM Net Retention Rate | C25: 1.13
B26: Color key: blue = hardcoded input | black = formula | green = cross-sheet link. Not investment advice. | C26: 368.7
B27: Large Customers (>$100K) | C27: 634

Sheet Model
A1: FSLY — DCF VALUATION MODEL (5-Year FCF, Gordon Growth Terminal)
A2: SINGLE WACC across all scenarios (mandatory). Only growth, FCF margin & terminal growth vary.
A4: HISTORICAL & BASE ($M)
A5: Metric | B5: Value
A6: FY2024 Revenue | B6: 543.676
A7: FY2025 Revenue | B7: 624.018
A8: FY2025 Non-GAAP Op Income | B8: 22.398
A9: FY2025 Adj. EBITDA | B9: 77.379
A10: FY2025 Free Cash Flow | B10: 45.809
A11: FY2026 Guided Revenue (Yr1 base) | B11: 717.5
A13: ASSUMPTIONS
A14: Assumption | C14: Bull | D14: Base | E14: Bear
A15: WACC (single, all scenarios) | C15: 0.11 | D15: 0.11 | E15: 0.11
A16: Yr2 Revenue Growth | C16: 0.2 | D16: 0.13 | E16: 0.09
A17: Yr3 Revenue Growth | C17: 0.18 | D17: 0.12 | E17: 0.07
A18: Yr4 Revenue Growth | C18: 0.16 | D18: 0.11 | E18: 0.06
A19: Yr5 Revenue Growth | C19: 0.14 | D19: 0.1 | E19: 0.05
A20: Yr1 FCF Margin | C20: 0.08 | D20: 0.07 | E20: 0.06
A21: Yr2 FCF Margin | C21: 0.13 | D21: 0.1 | E21: 0.07
A22: Yr3 FCF Margin | C22: 0.17 | D22: 0.13 | E22: 0.09
A23: Yr4 FCF Margin | C23: 0.22 | D23: 0.16 | E23: 0.11
A24: Yr5 FCF Margin (terminal) | C24: 0.26 | D24: 0.19 | E24: 0.13
A25: Terminal Growth Rate | C25: 0.045 | D25: 0.035 | E25: 0.03
A27: PROJECTIONS — REVENUE ($M)
A28: Year | B28: Bull | C28: Base | D28: Bear
A29: Yr1 (FY2026, guided) | B29: =$B$11 -> 717.5 | C29: =$B$11 -> 717.5 | D29: =$B$11 -> 717.5
A30: Yr2 (FY2027) | B30: =B29*(1+$C$16) -> 861 | C30: =C29*(1+$D$16) -> 810.775 | D30: =D29*(1+$E$16) -> 782.075
A31: Yr3 (FY2028) | B31: =B30*(1+$C$17) -> 1015.98 | C31: =C30*(1+$D$17) -> 908.068 | D31: =D30*(1+$E$17) -> 836.82025
A32: Yr4 (FY2029) | B32: =B31*(1+$C$18) -> 1178.5368 | C32: =C31*(1+$D$18) -> 1007.9555 | D32: =D31*(1+$E$18) -> 887.02946
A33: Yr5 (FY2030) | B33: =B32*(1+$C$19) -> 1343.532 | C33: =C32*(1+$D$19) -> 1108.751 | D33: =D32*(1+$E$19) -> 931.38094
A35: PROJECTIONS — FREE CASH FLOW ($M)
A36: Year | B36: Bull | C36: Base | D36: Bear
A37: Yr1 FCF | B37: =B29*$C$20 -> 57.4 | C37: =C29*$D$20 -> 50.225 | D37: =D29*$E$20 -> 43.05
A38: Yr2 FCF | B38: =B30*$C$21 -> 111.93 | C38: =C30*$D$21 -> 81.0775 | D38: =D30*$E$21 -> 54.74525
A39: Yr3 FCF | B39: =B31*$C$22 -> 172.7166 | C39: =C31*$D$22 -> 118.04884 | D39: =D31*$E$22 -> 75.313823
A40: Dashboard link row (Bull/Base/Bear) | B40: =B32*$C$23 -> 259.2781 | C40: =B52 -> 24.161294 | D40: =C52 -> 12.548002 | E40: =D52 -> 6.9721529
A41: Yr5 FCF | B41: =B33*$C$24 -> 349.31831 | C41: =C33*$D$24 -> 210.6627 | D41: =D33*$E$24 -> 121.07952
A43: DCF WATERFALL
A44: Item | B44: Bull | C44: Base | D44: Bear
A45: PV of 5-Yr FCF | B45: =B37/(1+$C$15)^1+B38/(1+$C$15)^2+B39/(1+$C$15)^3+B40/(1+$C$15)^4+B41/(1+$C$15)^5 -> 646.94343 | C45: =C37/(1+$D$15)^1+C38/(1+$D$15)^2+C39/(1+$D$15)^3+C40/(1+$D$15)^4+C41/(1+$D$15)^5 -> 338.30221 | D45: =D37/(1+$E$15)^1+D38/(1+$E$15)^2+D39/(1+$E$15)^3+D40/(1+$E$15)^4+D41/(1+$E$15)^5 -> 218.40564
...

Sheet Rule_of_40
A1: FSLY — RULE OF 40 ANALYSIS
A2: Rule of 40 = Revenue Growth % + Profitability Margin %. >40 healthy, >60 exceptional.
A4: FSLY SCORECARD
A5: Basis | B5: Growth % | C5: Margin % | D5: Rule of 40
A6: FY2025 — FCF margin | B6: 0.148 | C6: 0.073 | D6: =(B6+C6)*100 -> 22.1
A7: FY2025 — Adj. EBITDA margin | B7: 0.148 | C7: 0.124 | D7: =(B7+C7)*100 -> 27.2
A8: FY2025 — Non-GAAP op margin | B8: 0.148 | C8: 0.036 | D8: =(B8+C8)*100 -> 18.4
A9: FY2025 headline R40 (adj. EBITDA basis) | C9: =D7 -> 27.2
A11: Q1 2026 (ANNUALIZED YoY)
A12: Basis | B12: Growth % | C12: Margin % | D12: Rule of 40
A13: Q1 2026 — FCF margin | B13: 0.2 | C13: 0.024 | D13: =(B13+C13)*100 -> 22.4
A14: Q1 2026 — Adj. EBITDA margin | B14: 0.2 | C14: 0.17 | D14: =(B14+C14)*100 -> 37
A15: Q1 2026 — Non-GAAP op margin | B15: 0.2 | C15: 0.111 | D15: =(B15+C15)*100 -> 31.1
A16: Q1 2026 headline R40 (adj. EBITDA basis) | C16: =D14 -> 37
A19: PEER COMPARABLES (CDN / Edge / Security)
A20: Company | B20: Ticker | C20: Fwd Rev Growth | D20: FCF Margin (est.) | E20: Rule of 40 | F20: Fwd EV/Sales | G20: Note
A21: Fastly | B21: FSLY | C21: 0.16 | D21: 0.1 | E21: =(C21+D21)*100 -> 26 | F21: 4.3 | G21: Subject — accelerating Security + AI
A22: Cloudflare | B22: NET | C22: 0.3 | D22: 0.12 | E22: =(C22+D22)*100 -> 42 | F22: 28 | G22: Premium multiple; 30%+ growth
A23: Akamai | B23: AKAM | C23: 0.06 | D23: 0.22 | E23: =(C23+D23)*100 -> 28 | F23: 4.3 | G23: Mature; security/compute pivot
A24: Datadog | B24: DDOG | C24: 0.24 | D24: 0.27 | E24: =(C24+D24)*100 -> 51 | F24: 13 | G24: Observability; high R40
A25: Cloudflare-tier avg | B25: — | C25: 0.3 | D25: 0.12 | E25: =(C25+D25)*100 -> 42 | F25: 28 | G25: Hypergrowth comp
A26: CDN/infra avg | B26: — | C26: 0.1 | D26: 0.18 | E26: =(C26+D26)*100 -> 28 | F26: 4 | G26: Mature infra comp
A27: Limelight/Edgio (defunct) | B27: — | C27: n/a | D27: n/a | E27: n/a | F27: n/a | G27: Cautionary CDN comp
A29: Peer growth/FCF figures are approximate analyst estimates for context, not precise consensus.

Sheet Options_Strategy
A1: FSLY — OPTIONS OVERLAY (Income; existing 100–500 share position)
A2: Goal: generate income against shares. Elevated IV post-drop favors SELLING premium. Yields shown PER CYCLE.
A4: MARKET REFERENCE
A5: Current Price | B5: =Dashboard!C6 -> 20.09
A6: 50-Day SMA (resistance) | B6: 23.34
A7: 200-Day SMA (support) | B7: 17.14
A8: DCF Base Case | B8: =Model!D40 -> 12.548002
A9: DCF Bear Case | B9: =Model!E40 -> 6.9721529
A11: RECOMMENDED STRATEGIES (per 1 contract = 100 shares)
A12: Strategy | B12: Structure | C12: Net Premium / Cost | D12: Max Gain | E12: Max Loss / Risk | F12: Rationale
A13: Covered Call (primary) | B13: Sell $25 call, ~45–60 DTE (Aug 2026) | C13: +$1.00 (~$100/contract) | D13: Premium + $4.91 appreciation to $25 = ~$591/contract | E13: Caps upside above $25; keep shares unless called | F13: Income at/above 50-day SMA resistance. ~5% per-cycle yield on $20 stock. Strike above DCF base, near bull DCF.
A14: Cash-Secured Put (add) | B14: Sell $17.50 put, ~45 DTE | C14: +$0.70 (~$70/contract) | D14: $70 premium kept if above $17.50 | E14: Assigned at $17.50 (net ~$16.80) — $1,680 cash/contract | F14: Adds shares near DCF base/support if dips. ~4% per-cycle yield. Better entry toward intrinsic value.
A15: Collar (optional) | B15: Sell $25 call + buy $17 put, ~60 DTE | C15: ~$0.10 net credit | D15: Premium + appreciation to $25 | E15: Downside floored at $17 (near 200-day SMA) | F15: Protects gains given recent 38% drop; near-zero cost. Use if prioritizing protection over pure income.
A17: Position sizing (100–500 shares): 1–5 covered-call contracts. Size CSP cash so max assignment ($1,680/contract) stays within risk budget.
A18: Premiums are estimates pending live IV; verify on the chain. Yields are PER CYCLE, not annualized. Not investment advice.
